Workbook

Sheet คู่มือการใช้งาน
B1: คู่มือการใช้งานโปแกรมภาระงาน ใช้แทนโปรแกรม ตารางเวร
A3: 1 | B3: NN ผู้ป่วยแต่ละคน ICU,Sub-I= 12,อื่นๆ =4.5
A4: 2 | B4: สัดส่วนภาระงานตามเวรสามารถแก้ไขได้
A5: 3 | B5: ใส่จำนวนเจ้าหน้าที่ที่ปฏิบัติงานในเดือนนั้นๆโดยยกเว้นผู้ที่ลาคลอดหรือเรียนต่อที่ไม่มาทำงานทั้งเดือน
A6: 4 | B6: จำนวนวันราชการในเดือนนี้
A7: 5 | B7: ยอดผู้ป่วยให้ใช้ยอดคงพยาบาลปลายเวร
A8: 6 | B8: ประเภทผู้ป่วย ให้เอามาจากโปรแกรม ประเภทผู้ป่วยที่ลงทุกเวรอยู่แล้ว หลังจากเอางใน P4P แล้วเอามาลงที่นี่ด้วย
B9: ยอดผู้ป่วย กับ ยอดรวมแต่ละประเภท ต้องเท่ากัน

Sheet ต้นฉบับ
A1: การคิด FTEรายวัน
A2: หอผู้ป่วย…ทารกวิกฤต…...ประจำเดือน…ตุลาคม...........พ.ศ.....2567............
A3: NN ผู้ป่วยต่อคน | B3: 4.5 | C3: สัดส่วนตามเวร | E3: N | I3: D | M3: E | O3: ค่าเวร | Q3: =((F103+F105)*240)+((G103+G105)*180) -> 41760 | S3: บาท
E4: 0.25 | I4: 0.4 | M4: 0.35 | O4: ค่าOT | Q4: =((I103+L103+I104+L104+I105+L105)*660)+((J103+J105+J104)*530) -> 19140 | S4: บาท
A5: จำนวนพยาบาลมีจริงเดือนนี้ | C5: 13 | E5: คน | F5: จำนวนวันราชการเดือนนี้ | M5: 21 | N5: วัน
A6: จำนวนพยาบาลตามFTE | C6: =((C106*12)/(M5*7)+((D106*12)/(M5*7))) -> 35.07483 | E6: คน | F6: ขาดเกิน | I6: =C5-C6 -> -22.07483 | L6: คน | M6: product | N6: =((((C106*4.5)+(D106*12))/((F106+G106+H106+I106+J106+K106+L106)*7)))*100 -> 142.00627 | O6: product ตามประเภท | R6: =U106 -> 48.253471
A7: วันที่ | B7: เวร | C7: sick new born | D7: NICU | E7: FTE | F7: ขึ้นตามตารางเวร | L7: OT เสริม | M7: -ขาด/+เกิน | N7: product | O7: ประเภทผู้ป่วย | T7: รวม | U7: product ตามประเภท
F8: ไม่ใช่ OT | I8: OT | O8: 1 | P8: 2 | Q8: 3 | R8: 4 | S8: 5
F9: RN | G9: TN | H9: PN | I9: RN | J9: TN | K9: PN
A10: 1 | B10: N | C10: 10 | D10: 7 | E10: =((($B$3*C10)+(12*D10))*$E$4)/7 -> 4.6071429 | F10: 3 | G10: 0 | H10: 0 | M10: =(F10+G10+H10+L10)-E10 -> -1.6071429 | N10: =(((C10*4.5)+(12*D10))*$E$4)/((F10+G10+H10+I10+J10+K10+L10)*7)*100 -> 153.57143 | O10: 0 | P10: 0 | Q10: 9 | R10: 3 | S10: 5 | T10: =SUM(O10:S10) -> 17 | U10: =((((O10*1.5+(P10*3.5)+(Q10*5.5)+(R10*7.5)+(S10*12)))/3)/((F10+G10+H10+I10+J10+K10+L10)*7))*100 -> 209.52381 | V10: =C10+D10-T10 -> 0
B11: D | C11: 10 | D11: 8 | E11: =((($B$3*C11)+(12*D11))*$E$4)/7 -> 5.0357143 | F11: 4 | G11: 0 | H11: 0 | K11: 1 | M11: =(F11+G11+H11+L11)-E11 -> -1.0357143 | N11: =(((C11*4.5)+(12*D11))*$E$4)/((F11+G11+H11+I11+J11+K11+L11)*7)*100 -> 100.71429 | O11: 0 | P11: 0 | Q11: 10 | R11: 2 | S11: 6 | T11: =SUM(O11:S11) -> 18 | U11: =((((O11*1.5+(P11*3.5)+(Q11*5.5)+(R11*7.5)+(S11*12)))/3)/((F11+G11+H11+I11+J11+K11+L11)*7))*100 -> 135.2381 | V11: =C11+D11-T11 -> 0
B12: E | C12: 10 | D12: 8 | E12: =((($B$3*C12)+(12*D12))*$E$4)/7 -> 5.0357143 | F12: 3 | G12: 0 | H12: 0 | M12: =(F12+G12+H12+L12)-E12 -> -2.0357143 | N12: =(((C12*4.5)+(12*D12))*$E$4)/((F12+G12+H12+I12+J12+K12+L12)*7)*100 -> 167.85714 | O12: 0 | P12: 0 | Q12: 9 | R12: 3 | S12: 6 | T12: =SUM(O12:S12) -> 18 | U12: =((((O12*1.5+(P12*3.5)+(Q12*5.5)+(R12*7.5)+(S12*12)))/3)/((F12+G12+H12+I12+J12+K12+L12)*7))*100 -> 228.57143 | V12: =C12+D12-T12 -> 0
A13: 2 | B13: N | C13: 10 | D13: 8 | E13: =((($B$3*C13)+(12*D13))*$E$4)/7 -> 5.0357143 | F13: 3 | G13: 0 | H13: 0 | M13: =(F13+G13+H13+L13)-E13 -> -2.0357143 | N13: =(((C13*4.5)+(12*D13))*$E$4)/((F13+G13+H13+I13+J13+K13+L13)*7)*100 -> 167.85714 | O13: 0 | P13: 0 | Q13: 9 | R13: 3 | S13: 6 | T13: =SUM(O13:S13) -> 18 | U13: =((((O13*1.5+(P13*3.5)+(Q13*5.5)+(R13*7.5)+(S13*12)))/3)/((F13+G13+H13+I13+J13+K13+L13)*7))*100 -> 228.57143 | V13: =C13+D13-T13 -> 0
B14: D | C14: 10 | D14: 8 | E14: =((($B$3*C14)+(12*D14))*$E$4)/7 -> 5.0357143 | F14: 2 | G14: 0 | H14: 1 | I14: 1 | M14: =(F14+G14+H14+L14)-E14 -> -2.0357143 | N14: =(((C14*4.5)+(12*D14))*$E$4)/((F14+G14+H14+I14+J14+K14+L14)*7)*100 -> 125.89286 | O14: 0 | P14: 1 | Q14: 9 | R14: 3 | S14: 6 | T14: =SUM(O14:S14) -> 19 | U14: =((((O14*1.5+(P14*3.5)+(Q14*5.5)+(R14*7.5)+(S14*12)))/3)/((F14+G14+H14+I14+J14+K14+L14)*7))*100 -> 175.59524 | V14: =C14+D14-T14 -> -1
B15: E | C15: 11 | D15: 9 | E15: =((($B$3*C15)+(12*D15))*$E$4)/7 -> 5.625 | F15: 3 | G15: 0 | H15: 1 | M15: =(F15+G15+H15+L15)-E15 -> -1.625 | N15: =(((C15*4.5)+(12*D15))*$E$4)/((F15+G15+H15+I15+J15+K15+L15)*7)*100 -> 140.625 | O15: 0 | P15: 0 | Q15: 11 | R15: 3 | S15: 6 | T15: =SUM(O15:S15) -> 20 | U15: =((((O15*1.5+(P15*3.5)+(Q15*5.5)+(R15*7.5)+(S15*12)))/3)/((F15+G15+H15+I15+J15+K15+L15)*7))*100 -> 184.52381 | V15: =C15+D15-T15 -> 0
A16: 3 | B16: N | C16: 12 | D16: 8 | E16: =((($B$3*C16)+(12*D16))*$E$4)/7 -> 5.3571429 | F16: 2 | G16: 0 | H16: 0 | I16: 1 | M16: =(F16+G16+H16+L16)-E16 -> -3.3571429 | N16: =(((C16*4.5)+(12*D16))*$E$4)/((F16+G16+H16+I16+J16+K16+L16)*7)*100 -> 178.57143 | O16: 0 | P16: 0 | Q16: 9 | R16: 4 | S16: 7 | T16: =SUM(O16:S16) -> 20 | U16: =((((O16*1.5+(P16*3.5)+(Q16*5.5)+(R16*7.5)+(S16*12)))/3)/((F16+G16+H16+I16+J16+K16+L16)*7))*100 -> 259.52381 | V16: =C16+D16-T16 -> 0
B17: D | C17: 13 | D17: 8 | E17: =((($B$3*C17)+(12*D17))*$E$4)/7 -> 5.5178571 | F17: 4 | G17: 0 | K17: 1 | M17: =(F17+G17+H17+L17)-E17 -> -1.5178571 | N17: =(((C17*4.5)+(12*D17))*$E$4)/((F17+G17+H17+I17+J17+K17+L17)*7)*100 -> 110.35714 | O17: 0 | P17: 2 | Q17: 7 | R17: 4 | S17: 8 | T17: =SUM(O17:S17) -> 21 | U17: =((((O17*1.5+(P17*3.5)+(Q17*5.5)+(R17*7.5)+(S17*12)))/3)/((F17+G17+H17+I17+J17+K17+L17)*7))*100 -> 163.33333 | V17: =C17+D17-T17 -> 0
B18: E | C18: 12 | D18: 8 | E18: =((($B$3*C18)+(12*D18))*$E$4)/7 -> 5.3571429 | F18: 3 | G18: 0 | H18: 1 | M18: =(F18+G18+H18+L18)-E18 -> -1.3571429 | N18: =(((C18*4.5)+(12*D18))*$E$4)/((F18+G18+H18+I18+J18+K18+L18)*7)*100 -> 133.92857 | O18: 0 | P18: 0 | Q18: 9 | R18: 3 | S18: 8 | T18: =SUM(O18:S18) -> 20 | U18: =((((O18*1.5+(P18*3.5)+(Q18*5.5)+(R18*7.5)+(S18*12)))/3)/((F18+G18+H18+I18+J18+K18+L18)*7))*100 -> 200 | V18: =C18+D18-T18 -> 0
A19: 4 | B19: N | C19: 12 | D19: 8 | E19: =((($B$3*C19)+(12*D19))*$E$4)/7 -> 5.3571429 | F19: 2 | G19: 0 | H19: 0 | L19: 1 | M19: =(F19+G19+H19+L19)-E19 -> -2.3571429 | N19: =(((C19*4.5)+(12*D19))*$E$4)/((F19+G19+H19+I19+J19+K19+L19)*7)*100 -> 178.57143 | O19: 0 | P19: 0 | Q19: 9 | R19: 3 | S19: 8 | T19: =SUM(O19:S19) -> 20 | U19: =((((O19*1.5+(P19*3.5)+(Q19*5.5)+(R19*7.5)+(S19*12)))/3)/((F19+G19+H19+I19+J19+K19+L19)*7))*100 -> 266.66667 | V19: =C19+D19-T19 -> 0
B20: D | C20: 12 | D20: 8 | E20: =((($B$3*C20)+(12*D20))*$E$4)/7 -> 5.3571429 | F20: 3 | G20: 0 | H20: 1 | I20: 1 | M20: =(F20+G20+H20+L20)-E20 -> -1.3571429 | N20: =(((C20*4.5)+(12*D20))*$E$4)/((F20+G20+H20+I20+J20+K20+L20)*7)*100 -> 107.14286 | O20: 0 | P20: 0 | Q20: 9 | R20: 3 | S20: 8 | T20: =SUM(O20:S20) -> 20 | U20: =((((O20*1.5+(P20*3.5)+(Q20*5.5)+(R20*7.5)+(S20*12)))/3)/((F20+G20+H20+I20+J20+K20+L20)*7))*100 -> 160 | V20: =C20+D20-T20 -> 0
B21: E | C21: 11 | D21: 8 | E21: =((($B$3*C21)+(12*D21))*$E$4)/7 -> 5.1964286 | F21: 3 | G21: 0 | H21: 0 | K21: 1 | M21: =(F21+G21+H21+L21)-E21 -> -2.1964286 | N21: =(((C21*4.5)+(12*D21))*$E$4)/((F21+G21+H21+I21+J21+K21+L21)*7)*100 -> 129.91071 | O21: 0 | P21: 0 | Q21: 13 | R21: 2 | S21: 4 | T21: =SUM(O21:S21) -> 19 | U21: =((((O21*1.5+(P21*3.5)+(Q21*5.5)+(R21*7.5)+(S21*12)))/3)/((F21+G21+H21+I21+J21+K21+L21)*7))*100 -> 160.11905 | V21: =C21+D21-T21 -> 0
A22: 5 | B22: N | C22: 11 | D22: 8 | E22: =((($B$3*C22)+(12*D22))*$E$4)/7 -> 5.1964286 | F22: 2 | G22: 0 | H22: 0 | L22: 1 | M22: =(F22+G22+H22+L22)-E22 -> -2.1964286 | N22: =(((C22*4.5)+(12*D22))*$E$4)/((F22+G22+H22+I22+J22+K22+L22)*7)*100 -> 173.21429 | O22: 0 | P22: 0 | Q22: 12 | R22: 3 | S22: 4 | T22: =SUM(O22:S22) -> 19 | U22: =((((O22*1.5+(P22*3.5)+(Q22*5.5)+(R22*7.5)+(S22*12)))/3)/((F22+G22+H22+I22+J22+K22+L22)*7))*100 -> 216.66667 | V22: =C22+D22-T22 -> 0
B23: D | C23: 13 | D23: 8 | E23: =((($B$3*C23)+(12*D23))*$E$4)/7 -> 5.5178571 | F23: 2 | G23: 0 | H23: 1 | I23: 1 | K23: 1 | M23: =(F23+G23+H23+L23)-E23 -> -2.5178571 | N23: =(((C23*4.5)+(12*D23))*$E$4)/((F23+G23+H23+I23+J23+K23+L23)*7)*100 -> 110.35714 | O23: 0 | P23: 3 | Q23: 11 | R23: 3 | S23: 4 | T23: =SUM(O23:S23) -> 21 | U23: =((((O23*1.5+(P23*3.5)+(Q23*5.5)+(R23*7.5)+(S23*12)))/3)/((F23+G23+H23+I23+J23+K23+L23)*7))*100 -> 134.7619 | V23: =C23+D23-T23 -> 0
B24: E | C24: 12 | D24: 7 | E24: =((($B$3*C24)+(12*D24))*$E$4)/7 -> 4.9285714 | F24: 3 | G24: 0 | H24: 1 | M24: =(F24+G24+H24+L24)-E24 -> -0.92857143 | N24: =(((C24*4.5)+(12*D24))*$E$4)/((F24+G24+H24+I24+J24+K24+L24)*7)*100 -> 123.21429 | O24: 0 | P24: 0 | Q24: 13 | R24: 2 | S24: 4 | T24: =SUM(O24:S24) -> 19 | U24: =((((O24*1.5+(P24*3.5)+(Q24*5.5)+(R24*7.5)+(S24*12)))/3)/((F24+G24+H24+I24+J24+K24+L24)*7))*100 -> 160.11905 | V24: =C24+D24-T24 -> 0
A25: 6 | B25: N | C25: 11 | D25: 7 | E25: =((($B$3*C25)+(12*D25))*$E$4)/7 -> 4.7678571 | F25: 3 | G25: 0 | H25: 0 | M25: =(F25+G25+H25+L25)-E25 -> -1.7678571 | N25: =(((C25*4.5)+(12*D25))*$E$4)/((F25+G25+H25+I25+J25+K25+L25)*7)*100 -> 158.92857 | O25: 0 | P25: 0 | Q25: 13 | R25: 1 | S25: 4 | T25: =SUM(O25:S25) -> 18 | U25: =((((O25*1.5+(P25*3.5)+(Q25*5.5)+(R25*7.5)+(S25*12)))/3)/((F25+G25+H25+I25+J25+K25+L25)*7))*100 -> 201.5873 | V25: =C25+D25-T25 -> 0
B26: D | C26: 11 | D26: 7 | E26: =((($B$3*C26)+(12*D26))*$E$4)/7 -> 4.7678571 | F26: 3 | G26: 0 | K26: 1 | M26: =(F26+G26+H26+L26)-E26 -> -1.7678571 | N26: =(((C26*4.5)+(12*D26))*$E$4)/((F26+G26+H26+I26+J26+K26+L26)*7)*100 -> 119.19643 | O26: 0 | P26: 2 | Q26: 11 | R26: 1 | S26: 4 | T26: =SUM(O26:S26) -> 18 | U26: =((((O26*1.5+(P26*3.5)+(Q26*5.5)+(R26*7.5)+(S26*12)))/3)/((F26+G26+H26+I26+J26+K26+L26)*7))*100 -> 146.42857 | V26: =C26+D26-T26 -> 0
B27: E | C27: 10 | D27: 6 | E27: =((($B$3*C27)+(12*D27))*$E$4)/7 -> 4.1785714 | F27: 3 | G27: 0 | H27: 1 | K27: 1 | M27: =(F27+G27+H27+L27)-E27 -> -0.17857143 | N27: =(((C27*4.5)+(12*D27))*$E$4)/((F27+G27+H27+I27+J27+K27+L27)*7)*100 -> 83.571429 | O27: 0 | P27: 0 | Q27: 12 | R27: 1 | S27: 3 | T27: =SUM(O27:S27) -> 16 | U27: =((((O27*1.5+(P27*3.5)+(Q27*5.5)+(R27*7.5)+(S27*12)))/3)/((F27+G27+H27+I27+J27+K27+L27)*7))*100 -> 104.28571 | V27: =C27+D27-T27 -> 0
A28: 7 | B28: N | C28: 9 | D28: 6 | E28: =((($B$3*C28)+(12*D28))*$E$4)/7 -> 4.0178571 | F28: 3 | G28: 0 | H28: 1 | M28: =(F28+G28+H28+L28)-E28 -> -0.017857143 | N28: =(((C28*4.5)+(12*D28))*$E$4)/((F28+G28+H28+I28+J28+K28+L28)*7)*100 -> 100.44643 | O28: 0 | P28: 0 | Q28: 11 | R28: 1 | S28: 3 | T28: =SUM(O28:S28) -> 15 | U28: =((((O28*1.5+(P28*3.5)+(Q28*5.5)+(R28*7.5)+(S28*12)))/3)/((F28+G28+H28+I28+J28+K28+L28)*7))*100 -> 123.80952 | V28: =C28+D28-T28 -> 0
B29: D | C29: 11 | D29: 5 | E29: =((($B$3*C29)+(12*D29))*$E$4)/7 -> 3.9107143 | F29: 4 | G29: 0 | H29: 1 | M29: =(F29+G29+H29+L29)-E29 -> 1.0892857 | N29: =(((C29*4.5)+(12*D29))*$E$4)/((F29+G29+H29+I29+J29+K29+L29)*7)*100 -> 78.214286 | O29: 0 | P29: 2 | Q29: 10 | R29: 0 | S29: 4 | T29: =SUM(O29:S29) -> 16 | U29: =((((O29*1.5+(P29*3.5)+(Q29*5.5)+(R29*7.5)+(S29*12)))/3)/((F29+G29+H29+I29+J29+K29+L29)*7))*100 -> 104.7619 | V29: =C29+D29-T29 -> 0
B30: E | C30: 10 | D30: 5 | E30: =((($B$3*C30)+(12*D30))*$E$4)/7 -> 3.75 | F30: 1 | G30: 0 | H30: 0 | I30: 1 | L30: 1 | M30: =(F30+G30+H30+L30)-E30 -> -1.75 | N30: =(((C30*4.5)+(12*D30))*$E$4)/((F30+G30+H30+I30+J30+K30+L30)*7)*100 -> 125 | O30: 0 | P30: 0 | Q30: 11 | R30: 1 | S30: 3 | T30: =SUM(O30:S30) -> 15 | U30: =((((O30*1.5+(P30*3.5)+(Q30*5.5)+(R30*7.5)+(S30*12)))/3)/((F30+G30+H30+I30+J30+K30+L30)*7))*100 -> 165.07937 | V30: =C30+D30-T30 -> 0
A31: 8 | B31: N | C31: 10 | D31: 7 | E31: =((($B$3*C31)+(12*D31))*$E$4)/7 -> 4.6071429 | F31: 3 | G31: 0 | H31: 0 | M31: =(F31+G31+H31+L31)-E31 -> -1.6071429 | N31: =(((C31*4.5)+(12*D31))*$E$4)/((F31+G31+H31+I31+J31+K31+L31)*7)*100 -> 153.57143 | O31: 0 | P31: 0 | Q31: 11 | R31: 1 | S31: 5 | T31: =SUM(O31:S31) -> 17 | U31: =((((O31*1.5+(P31*3.5)+(Q31*5.5)+(R31*7.5)+(S31*12)))/3)/((F31+G31+H31+I31+J31+K31+L31)*7))*100 -> 203.1746 | V31: =C31+D31-T31 -> 0
B32: D | C32: 10 | D32: 6 | E32: =((($B$3*C32)+(12*D32))*$E$4)/7 -> 4.1785714 | F32: 3 | G32: 0 | H32: 0 | I32: 0 | J32: 0 | K32: 0 | M32: =(F32+G32+H32+L32)-E32 -> -1.1785714 | N32: =(((C32*4.5)+(12*D32))*$E$4)/((F32+G32+H32+I32+J32+K32+L32)*7)*100 -> 139.28571 | O32: 0 | P32: 2 | Q32: 8 | R32: 1 | S32: 5 | T32: =SUM(O32:S32) -> 16 | U32: =((((O32*1.5+(P32*3.5)+(Q32*5.5)+(R32*7.5)+(S32*12)))/3)/((F32+G32+H32+I32+J32+K32+L32)*7))*100 -> 188.09524 | V32: =C32+D32-T32 -> 0
B33: E | C33: 11 | D33: 6 | E33: =((($B$3*C33)+(12*D33))*$E$4)/7 -> 4.3392857 | F33: 3 | G33: 0 | H33: 0 | I33: 0 | J33: 0 | K33: 0 | L33: 0 | M33: =(F33+G33+H33+L33)-E33 -> -1.3392857 | N33: =(((C33*4.5)+(12*D33))*$E$4)/((F33+G33+H33+I33+J33+K33+L33)*7)*100 -> 144.64286 | O33: 0 | P33: 0 | Q33: 10 | R33: 2 | S33: 5 | T33: =SUM(O33:S33) -> 17 | U33: =((((O33*1.5+(P33*3.5)+(Q33*5.5)+(R33*7.5)+(S33*12)))/3)/((F33+G33+H33+I33+J33+K33+L33)*7))*100 -> 206.34921 | V33: =C33+D33-T33 -> 0
A34: 9 | B34: N | C34: 12 | D34: 6 | E34: =((($B$3*C34)+(12*D34))*$E$4)/7 -> 4.5 | F34: 3 | G34: 0 | H34: 0 | I34: 0 | J34: 0 | K34: 0 | L34: 0 | M34: =(F34+G34+H34+L34)-E34 -> -1.5 | N34: =(((C34*4.5)+(12*D34))*$E$4)/((F34+G34+H34+I34+J34+K34+L34)*7)*100 -> 150 | O34: 0 | P34: 0 | Q34: 10 | R34: 3 | S34: 5 | T34: =SUM(O34:S34) -> 18 | U34: =((((O34*1.5+(P34*3.5)+(Q34*5.5)+(R34*7.5)+(S34*12)))/3)/((F34+G34+H34+I34+J34+K34+L34)*7))*100 -> 218.25397 | V34: =C34+D34-T34 -> 0
B35: D | C35: 12 | D35: 6 | E35: =((($B$3*C35)+(12*D35))*$E$4)/7 -> 4.5 | F35: 4 | G35: 0 | H35: 0 | I35: 0 | J35: 0 | K35: 0 | L35: 0 | M35: =(F35+G35+H35+L35)-E35 -> -0.5 | N35: =(((C35*4.5)+(12*D35))*$E$4)/((F35+G35+H35+I35+J35+K35+L35)*7)*100 -> 112.5 | O35: 0 | P35: 2 | Q35: 9 | R35: 2 | S35: 5 | T35: =SUM(O35:S35) -> 18 | U35: =((((O35*1.5+(P35*3.5)+(Q35*5.5)+(R35*7.5)+(S35*12)))/3)/((F35+G35+H35+I35+J35+K35+L35)*7))*100 -> 156.54762 | V35: =C35+D35-T35 -> 0
B36: E | C36: 11 | D36: 6 | E36: =((($B$3*C36)+(12*D36))*$E$4)/7 -> 4.3392857 | F36: 3 | G36: 0 | H36: 0 | I36: 0 | J36: 0 | K36: 0 | L36: 0 | M36: =(F36+G36+H36+L36)-E36 -> -1.3392857 | N36: =(((C36*4.5)+(12*D36))*$E$4)/((F36+G36+H36+I36+J36+K36+L36)*7)*100 -> 144.64286 | O36: 0 | P36: 0 | Q36: 10 | R36: 2 | S36: 5 | T36: =SUM(O36:S36) -> 17 | U36: =((((O36*1.5+(P36*3.5)+(Q36*5.5)+(R36*7.5)+(S36*12)))/3)/((F36+G36+H36+I36+J36+K36+L36)*7))*100 -> 206.34921 | V36: =C36+D36-T36 -> 0
A37: 10 | B37: N | C37: 11 | D37: 6 | E37: =((($B$3*C37)+(12*D37))*$E$4)/7 -> 4.3392857 | F37: 3 | G37: 0 | H37: 0 | I37: 0 | J37: 0 | K37: 0 | L37: 0 | M37: =(F37+G37+H37+L37)-E37 -> -1.3392857 | N37: =(((C37*4.5)+(12*D37))*$E$4)/((F37+G37+H37+I37+J37+K37+L37)*7)*100 -> 144.64286 | O37: 0 | P37: 0 | Q37: 10 | R37: 2 | S37: 5 | T37: =SUM(O37:S37) -> 17 | U37: =((((O37*1.5+(P37*3.5)+(Q37*5.5)+(R37*7.5)+(S37*12)))/3)/((F37+G37+H37+I37+J37+K37+L37)*7))*100 -> 206.34921 | V37: =C37+D37-T37 -> 0
B38: D | C38: 11 | D38: 6 | E38: =((($B$3*C38)+(12*D38))*$E$4)/7 -> 4.3392857 | F38: 2 | G38: 0 | H38: 0 | I38: 2 | J38: 0 | K38: 0 | L38: 0 | M38: =(F38+G38+H38+L38)-E38 -> -2.3392857 | N38: =(((C38*4.5)+(12*D38))*$E$4)/((F38+G38+H38+I38+J38+K38+L38)*7)*100 -> 108.48214 | O38: 0 | P38: 1 | Q38: 9 | R38: 2 | S38: 5 | T38: =SUM(O38:S38) -> 17 | U38: =((((O38*1.5+(P38*3.5)+(Q38*5.5)+(R38*7.5)+(S38*12)))/3)/((F38+G38+H38+I38+J38+K38+L38)*7))*100 -> 152.38095 | V38: =C38+D38-T38 -> 0
B39: E | C39: 10 | D39: 6 | E39: =((($B$3*C39)+(12*D39))*$E$4)/7 -> 4.1785714 | F39: 3 | G39: 0 | H39: 1 | I39: 0 | J39: 0 | K39: 0 | L39: 0 | M39: =(F39+G39+H39+L39)-E39 -> -0.17857143 | N39: =(((C39*4.5)+(12*D39))*$E$4)/((F39+G39+H39+I39+J39+K39+L39)*7)*100 -> 104.46429 | O39: 0 | P39: 0 | Q39: 11 | R39: 2 | S39: 3 | T39: =SUM(O39:S39) -> 16 | U39: =((((O39*1.5+(P39*3.5)+(Q39*5.5)+(R39*7.5)+(S39*12)))/3)/((F39+G39+H39+I39+J39+K39+L39)*7))*100 -> 132.7381 | V39: =C39+D39-T39 -> 0
A40: 11 | B40: N | C40: 11 | D40: 6 | E40: =((($B$3*C40)+(12*D40))*$E$4)/7 -> 4.3392857 | F40: 3 | G40: 0 | H40: 0 | I40: 0 | J40: 0 | K40: 0 | L40: 0 | M40: =(F40+G40+H40+L40)-E40 -> -1.3392857 | N40: =(((C40*4.5)+(12*D40))*$E$4)/((F40+G40+H40+I40+J40+K40+L40)*7)*100 -> 144.64286 | O40: 0 | P40: 0 | Q40: 12 | R40: 2 | S40: 3 | T40: =SUM(O40:S40) -> 17 | U40: =((((O40*1.5+(P40*3.5)+(Q40*5.5)+(R40*7.5)+(S40*12)))/3)/((F40+G40+H40+I40+J40+K40+L40)*7))*100 -> 185.71429 | V40: =C40+D40-T40 -> 0
...

Sheet ต.ค
A1: การคิด FTEรายวัน
A2: หอผู้ป่วย……...ประจำเดือน..............พ.ศ.................
A3: NN ผู้ป่วยต่อคน | B3: 4.5 | C3: สัดส่วนตามเวร | E3: N | I3: D | M3: E | O3: ค่าเวร | Q3: =((F103+F105)*240)+((G103+G105)*180) -> 0 | S3: บาท
E4: 0.25 | I4: 0.4 | M4: 0.35 | O4: ค่าOT | Q4: =((I103+L103+I104+L104+I105+L105)*660)+((J103+J105+J104)*530) -> 0 | S4: บาท
A5: จำนวนพยาบาลมีจริงเดือนนี้ | E5: คน | F5: จำนวนวันราชการเดือนนี้ | N5: วัน
A6: จำนวนพยาบาลตามFTE | C6: =((C106*12)/(M5*7)+((D106*12)/(M5*7))) -> #DIV/0! | E6: คน | F6: ขาดเกิน | I6: =C5-C6 -> #DIV/0! | L6: คน | M6: product | N6: =((((C106*4.5)+(D106*12))/((F106+G106+H106+I106+J106+K106+L106)*7)))*100 -> #DIV/0! | O6: product ตามประเภท | R6: =U106 -> #DIV/0!
A7: วันที่ | B7: เวร | C7: sick new born | D7: NICU | E7: FTE | F7: ขึ้นตามตารางเวร | L7: OT เสริม | M7: -ขาด/+เกิน | N7: product | O7: ประเภทผู้ป่วย | T7: รวม | U7: product ตามประเภท
F8: ไม่ใช่ OT | I8: OT | O8: 1 | P8: 2 | Q8: 3 | R8: 4 | S8: 5
F9: RN | G9: TN | H9: PN | I9: RN | J9: TN | K9: PN
A10: 1 | B10: N | E10: =((($B$3*C10)+(12*D10))*$E$4)/7 -> 0 | M10: =(F10+G10+H10+L10)-E10 -> 0 | N10: =(((C10*12)+(12*D10))*$E$4)/((F10+G10+H10+I10+J10+K10+L10)*7)*100 -> #DIV/0! | T10: =SUM(O10:S10) -> 0 | U10: =((((O10*1.5+(P10*3.5)+(Q10*5.5)+(R10*7.5)+(S10*12)))/3)/((F10+G10+H10+I10+J10+K10+L10)*7))*100 -> #DIV/0! | V10: =C10+D10-T10 -> 0
B11: D | E11: =((($B$3*C11)+(12*D11))*$E$4)/7 -> 0 | M11: =(F11+G11+H11+L11)-E11 -> 0 | N11: =(((C11*12)+(12*D11))*$E$4)/((F11+G11+H11+I11+J11+K11+L11)*7)*100 -> #DIV/0! | T11: =SUM(O11:S11) -> 0 | U11: =((((O11*1.5+(P11*3.5)+(Q11*5.5)+(R11*7.5)+(S11*12)))/3)/((F11+G11+H11+I11+J11+K11+L11)*7))*100 -> #DIV/0! | V11: =C11+D11-T11 -> 0
B12: E | E12: =((($B$3*C12)+(12*D12))*$E$4)/7 -> 0 | M12: =(F12+G12+H12+L12)-E12 -> 0 | N12: =(((C12*12)+(12*D12))*$E$4)/((F12+G12+H12+I12+J12+K12+L12)*7)*100 -> #DIV/0! | T12: =SUM(O12:S12) -> 0 | U12: =((((O12*1.5+(P12*3.5)+(Q12*5.5)+(R12*7.5)+(S12*12)))/3)/((F12+G12+H12+I12+J12+K12+L12)*7))*100 -> #DIV/0! | V12: =C12+D12-T12 -> 0
A13: 2 | B13: N | E13: =((($B$3*C13)+(12*D13))*$E$4)/7 -> 0 | M13: =(F13+G13+H13+L13)-E13 -> 0 | N13: =(((C13*12)+(12*D13))*$E$4)/((F13+G13+H13+I13+J13+K13+L13)*7)*100 -> #DIV/0! | T13: =SUM(O13:S13) -> 0 | U13: =((((O13*1.5+(P13*3.5)+(Q13*5.5)+(R13*7.5)+(S13*12)))/3)/((F13+G13+H13+I13+J13+K13+L13)*7))*100 -> #DIV/0! | V13: =C13+D13-T13 -> 0
B14: D | E14: =((($B$3*C14)+(12*D14))*$E$4)/7 -> 0 | M14: =(F14+G14+H14+L14)-E14 -> 0 | N14: =(((C14*12)+(12*D14))*$E$4)/((F14+G14+H14+I14+J14+K14+L14)*7)*100 -> #DIV/0! | T14: =SUM(O14:S14) -> 0 | U14: =((((O14*1.5+(P14*3.5)+(Q14*5.5)+(R14*7.5)+(S14*12)))/3)/((F14+G14+H14+I14+J14+K14+L14)*7))*100 -> #DIV/0! | V14: =C14+D14-T14 -> 0
B15: E | E15: =((($B$3*C15)+(12*D15))*$E$4)/7 -> 0 | M15: =(F15+G15+H15+L15)-E15 -> 0 | N15: =(((C15*12)+(12*D15))*$E$4)/((F15+G15+H15+I15+J15+K15+L15)*7)*100 -> #DIV/0! | T15: =SUM(O15:S15) -> 0 | U15: =((((O15*1.5+(P15*3.5)+(Q15*5.5)+(R15*7.5)+(S15*12)))/3)/((F15+G15+H15+I15+J15+K15+L15)*7))*100 -> #DIV/0! | V15: =C15+D15-T15 -> 0
A16: 3 | B16: N | E16: =((($B$3*C16)+(12*D16))*$E$4)/7 -> 0 | M16: =(F16+G16+H16+L16)-E16 -> 0 | N16: =(((C16*12)+(12*D16))*$E$4)/((F16+G16+H16+I16+J16+K16+L16)*7)*100 -> #DIV/0! | T16: =SUM(O16:S16) -> 0 | U16: =((((O16*1.5+(P16*3.5)+(Q16*5.5)+(R16*7.5)+(S16*12)))/3)/((F16+G16+H16+I16+J16+K16+L16)*7))*100 -> #DIV/0! | V16: =C16+D16-T16 -> 0
B17: D | E17: =((($B$3*C17)+(12*D17))*$E$4)/7 -> 0 | M17: =(F17+G17+H17+L17)-E17 -> 0 | N17: =(((C17*12)+(12*D17))*$E$4)/((F17+G17+H17+I17+J17+K17+L17)*7)*100 -> #DIV/0! | T17: =SUM(O17:S17) -> 0 | U17: =((((O17*1.5+(P17*3.5)+(Q17*5.5)+(R17*7.5)+(S17*12)))/3)/((F17+G17+H17+I17+J17+K17+L17)*7))*100 -> #DIV/0! | V17: =C17+D17-T17 -> 0
B18: E | E18: =((($B$3*C18)+(12*D18))*$E$4)/7 -> 0 | M18: =(F18+G18+H18+L18)-E18 -> 0 | N18: =(((C18*12)+(12*D18))*$E$4)/((F18+G18+H18+I18+J18+K18+L18)*7)*100 -> #DIV/0! | T18: =SUM(O18:S18) -> 0 | U18: =((((O18*1.5+(P18*3.5)+(Q18*5.5)+(R18*7.5)+(S18*12)))/3)/((F18+G18+H18+I18+J18+K18+L18)*7))*100 -> #DIV/0! | V18: =C18+D18-T18 -> 0
A19: 4 | B19: N | E19: =((($B$3*C19)+(12*D19))*$E$4)/7 -> 0 | M19: =(F19+G19+H19+L19)-E19 -> 0 | N19: =(((C19*12)+(12*D19))*$E$4)/((F19+G19+H19+I19+J19+K19+L19)*7)*100 -> #DIV/0! | T19: =SUM(O19:S19) -> 0 | U19: =((((O19*1.5+(P19*3.5)+(Q19*5.5)+(R19*7.5)+(S19*12)))/3)/((F19+G19+H19+I19+J19+K19+L19)*7))*100 -> #DIV/0! | V19: =C19+D19-T19 -> 0
B20: D | E20: =((($B$3*C20)+(12*D20))*$E$4)/7 -> 0 | M20: =(F20+G20+H20+L20)-E20 -> 0 | N20: =(((C20*12)+(12*D20))*$E$4)/((F20+G20+H20+I20+J20+K20+L20)*7)*100 -> #DIV/0! | T20: =SUM(O20:S20) -> 0 | U20: =((((O20*1.5+(P20*3.5)+(Q20*5.5)+(R20*7.5)+(S20*12)))/3)/((F20+G20+H20+I20+J20+K20+L20)*7))*100 -> #DIV/0! | V20: =C20+D20-T20 -> 0
B21: E | E21: =((($B$3*C21)+(12*D21))*$E$4)/7 -> 0 | M21: =(F21+G21+H21+L21)-E21 -> 0 | N21: =(((C21*12)+(12*D21))*$E$4)/((F21+G21+H21+I21+J21+K21+L21)*7)*100 -> #DIV/0! | T21: =SUM(O21:S21) -> 0 | U21: =((((O21*1.5+(P21*3.5)+(Q21*5.5)+(R21*7.5)+(S21*12)))/3)/((F21+G21+H21+I21+J21+K21+L21)*7))*100 -> #DIV/0! | V21: =C21+D21-T21 -> 0
A22: 5 | B22: N | E22: =((($B$3*C22)+(12*D22))*$E$4)/7 -> 0 | M22: =(F22+G22+H22+L22)-E22 -> 0 | N22: =(((C22*12)+(12*D22))*$E$4)/((F22+G22+H22+I22+J22+K22+L22)*7)*100 -> #DIV/0! | T22: =SUM(O22:S22) -> 0 | U22: =((((O22*1.5+(P22*3.5)+(Q22*5.5)+(R22*7.5)+(S22*12)))/3)/((F22+G22+H22+I22+J22+K22+L22)*7))*100 -> #DIV/0! | V22: =C22+D22-T22 -> 0
B23: D | E23: =((($B$3*C23)+(12*D23))*$E$4)/7 -> 0 | M23: =(F23+G23+H23+L23)-E23 -> 0 | N23: =(((C23*12)+(12*D23))*$E$4)/((F23+G23+H23+I23+J23+K23+L23)*7)*100 -> #DIV/0! | T23: =SUM(O23:S23) -> 0 | U23: =((((O23*1.5+(P23*3.5)+(Q23*5.5)+(R23*7.5)+(S23*12)))/3)/((F23+G23+H23+I23+J23+K23+L23)*7))*100 -> #DIV/0! | V23: =C23+D23-T23 -> 0
B24: E | E24: =((($B$3*C24)+(12*D24))*$E$4)/7 -> 0 | M24: =(F24+G24+H24+L24)-E24 -> 0 | N24: =(((C24*12)+(12*D24))*$E$4)/((F24+G24+H24+I24+J24+K24+L24)*7)*100 -> #DIV/0! | T24: =SUM(O24:S24) -> 0 | U24: =((((O24*1.5+(P24*3.5)+(Q24*5.5)+(R24*7.5)+(S24*12)))/3)/((F24+G24+H24+I24+J24+K24+L24)*7))*100 -> #DIV/0! | V24: =C24+D24-T24 -> 0
A25: 6 | B25: N | E25: =((($B$3*C25)+(12*D25))*$E$4)/7 -> 0 | M25: =(F25+G25+H25+L25)-E25 -> 0 | N25: =(((C25*12)+(12*D25))*$E$4)/((F25+G25+H25+I25+J25+K25+L25)*7)*100 -> #DIV/0! | T25: =SUM(O25:S25) -> 0 | U25: =((((O25*1.5+(P25*3.5)+(Q25*5.5)+(R25*7.5)+(S25*12)))/3)/((F25+G25+H25+I25+J25+K25+L25)*7))*100 -> #DIV/0! | V25: =C25+D25-T25 -> 0
B26: D | E26: =((($B$3*C26)+(12*D26))*$E$4)/7 -> 0 | M26: =(F26+G26+H26+L26)-E26 -> 0 | N26: =(((C26*12)+(12*D26))*$E$4)/((F26+G26+H26+I26+J26+K26+L26)*7)*100 -> #DIV/0! | T26: =SUM(O26:S26) -> 0 | U26: =((((O26*1.5+(P26*3.5)+(Q26*5.5)+(R26*7.5)+(S26*12)))/3)/((F26+G26+H26+I26+J26+K26+L26)*7))*100 -> #DIV/0! | V26: =C26+D26-T26 -> 0
B27: E | E27: =((($B$3*C27)+(12*D27))*$E$4)/7 -> 0 | M27: =(F27+G27+H27+L27)-E27 -> 0 | N27: =(((C27*12)+(12*D27))*$E$4)/((F27+G27+H27+I27+J27+K27+L27)*7)*100 -> #DIV/0! | T27: =SUM(O27:S27) -> 0 | U27: =((((O27*1.5+(P27*3.5)+(Q27*5.5)+(R27*7.5)+(S27*12)))/3)/((F27+G27+H27+I27+J27+K27+L27)*7))*100 -> #DIV/0! | V27: =C27+D27-T27 -> 0
A28: 7 | B28: N | E28: =((($B$3*C28)+(12*D28))*$E$4)/7 -> 0 | M28: =(F28+G28+H28+L28)-E28 -> 0 | N28: =(((C28*12)+(12*D28))*$E$4)/((F28+G28+H28+I28+J28+K28+L28)*7)*100 -> #DIV/0! | T28: =SUM(O28:S28) -> 0 | U28: =((((O28*1.5+(P28*3.5)+(Q28*5.5)+(R28*7.5)+(S28*12)))/3)/((F28+G28+H28+I28+J28+K28+L28)*7))*100 -> #DIV/0! | V28: =C28+D28-T28 -> 0
B29: D | E29: =((($B$3*C29)+(12*D29))*$E$4)/7 -> 0 | M29: =(F29+G29+H29+L29)-E29 -> 0 | N29: =(((C29*12)+(12*D29))*$E$4)/((F29+G29+H29+I29+J29+K29+L29)*7)*100 -> #DIV/0! | T29: =SUM(O29:S29) -> 0 | U29: =((((O29*1.5+(P29*3.5)+(Q29*5.5)+(R29*7.5)+(S29*12)))/3)/((F29+G29+H29+I29+J29+K29+L29)*7))*100 -> #DIV/0! | V29: =C29+D29-T29 -> 0
B30: E | E30: =((($B$3*C30)+(12*D30))*$E$4)/7 -> 0 | M30: =(F30+G30+H30+L30)-E30 -> 0 | N30: =(((C30*12)+(12*D30))*$E$4)/((F30+G30+H30+I30+J30+K30+L30)*7)*100 -> #DIV/0! | T30: =SUM(O30:S30) -> 0 | U30: =((((O30*1.5+(P30*3.5)+(Q30*5.5)+(R30*7.5)+(S30*12)))/3)/((F30+G30+H30+I30+J30+K30+L30)*7))*100 -> #DIV/0! | V30: =C30+D30-T30 -> 0
A31: 8 | B31: N | E31: =((($B$3*C31)+(12*D31))*$E$4)/7 -> 0 | M31: =(F31+G31+H31+L31)-E31 -> 0 | N31: =(((C31*12)+(12*D31))*$E$4)/((F31+G31+H31+I31+J31+K31+L31)*7)*100 -> #DIV/0! | T31: =SUM(O31:S31) -> 0 | U31: =((((O31*1.5+(P31*3.5)+(Q31*5.5)+(R31*7.5)+(S31*12)))/3)/((F31+G31+H31+I31+J31+K31+L31)*7))*100 -> #DIV/0! | V31: =C31+D31-T31 -> 0
B32: D | E32: =((($B$3*C32)+(12*D32))*$E$4)/7 -> 0 | M32: =(F32+G32+H32+L32)-E32 -> 0 | N32: =(((C32*12)+(12*D32))*$E$4)/((F32+G32+H32+I32+J32+K32+L32)*7)*100 -> #DIV/0! | T32: =SUM(O32:S32) -> 0 | U32: =((((O32*1.5+(P32*3.5)+(Q32*5.5)+(R32*7.5)+(S32*12)))/3)/((F32+G32+H32+I32+J32+K32+L32)*7))*100 -> #DIV/0! | V32: =C32+D32-T32 -> 0
B33: E | E33: =((($B$3*C33)+(12*D33))*$E$4)/7 -> 0 | M33: =(F33+G33+H33+L33)-E33 -> 0 | N33: =(((C33*12)+(12*D33))*$E$4)/((F33+G33+H33+I33+J33+K33+L33)*7)*100 -> #DIV/0! | T33: =SUM(O33:S33) -> 0 | U33: =((((O33*1.5+(P33*3.5)+(Q33*5.5)+(R33*7.5)+(S33*12)))/3)/((F33+G33+H33+I33+J33+K33+L33)*7))*100 -> #DIV/0! | V33: =C33+D33-T33 -> 0
A34: 9 | B34: N | E34: =((($B$3*C34)+(12*D34))*$E$4)/7 -> 0 | M34: =(F34+G34+H34+L34)-E34 -> 0 | N34: =(((C34*12)+(12*D34))*$E$4)/((F34+G34+H34+I34+J34+K34+L34)*7)*100 -> #DIV/0! | T34: =SUM(O34:S34) -> 0 | U34: =((((O34*1.5+(P34*3.5)+(Q34*5.5)+(R34*7.5)+(S34*12)))/3)/((F34+G34+H34+I34+J34+K34+L34)*7))*100 -> #DIV/0! | V34: =C34+D34-T34 -> 0
B35: D | E35: =((($B$3*C35)+(12*D35))*$E$4)/7 -> 0 | M35: =(F35+G35+H35+L35)-E35 -> 0 | N35: =(((C35*12)+(12*D35))*$E$4)/((F35+G35+H35+I35+J35+K35+L35)*7)*100 -> #DIV/0! | T35: =SUM(O35:S35) -> 0 | U35: =((((O35*1.5+(P35*3.5)+(Q35*5.5)+(R35*7.5)+(S35*12)))/3)/((F35+G35+H35+I35+J35+K35+L35)*7))*100 -> #DIV/0! | V35: =C35+D35-T35 -> 0
B36: E | E36: =((($B$3*C36)+(12*D36))*$E$4)/7 -> 0 | M36: =(F36+G36+H36+L36)-E36 -> 0 | N36: =(((C36*12)+(12*D36))*$E$4)/((F36+G36+H36+I36+J36+K36+L36)*7)*100 -> #DIV/0! | T36: =SUM(O36:S36) -> 0 | U36: =((((O36*1.5+(P36*3.5)+(Q36*5.5)+(R36*7.5)+(S36*12)))/3)/((F36+G36+H36+I36+J36+K36+L36)*7))*100 -> #DIV/0! | V36: =C36+D36-T36 -> 0
A37: 10 | B37: N | E37: =((($B$3*C37)+(12*D37))*$E$4)/7 -> 0 | M37: =(F37+G37+H37+L37)-E37 -> 0 | N37: =(((C37*12)+(12*D37))*$E$4)/((F37+G37+H37+I37+J37+K37+L37)*7)*100 -> #DIV/0! | T37: =SUM(O37:S37) -> 0 | U37: =((((O37*1.5+(P37*3.5)+(Q37*5.5)+(R37*7.5)+(S37*12)))/3)/((F37+G37+H37+I37+J37+K37+L37)*7))*100 -> #DIV/0! | V37: =C37+D37-T37 -> 0
B38: D | E38: =((($B$3*C38)+(12*D38))*$E$4)/7 -> 0 | M38: =(F38+G38+H38+L38)-E38 -> 0 | N38: =(((C38*12)+(12*D38))*$E$4)/((F38+G38+H38+I38+J38+K38+L38)*7)*100 -> #DIV/0! | T38: =SUM(O38:S38) -> 0 | U38: =((((O38*1.5+(P38*3.5)+(Q38*5.5)+(R38*7.5)+(S38*12)))/3)/((F38+G38+H38+I38+J38+K38+L38)*7))*100 -> #DIV/0! | V38: =C38+D38-T38 -> 0
B39: E | E39: =((($B$3*C39)+(12*D39))*$E$4)/7 -> 0 | M39: =(F39+G39+H39+L39)-E39 -> 0 | N39: =(((C39*12)+(12*D39))*$E$4)/((F39+G39+H39+I39+J39+K39+L39)*7)*100 -> #DIV/0! | T39: =SUM(O39:S39) -> 0 | U39: =((((O39*1.5+(P39*3.5)+(Q39*5.5)+(R39*7.5)+(S39*12)))/3)/((F39+G39+H39+I39+J39+K39+L39)*7))*100 -> #DIV/0! | V39: =C39+D39-T39 -> 0
A40: 11 | B40: N | E40: =((($B$3*C40)+(12*D40))*$E$4)/7 -> 0 | M40: =(F40+G40+H40+L40)-E40 -> 0 | N40: =(((C40*12)+(12*D40))*$E$4)/((F40+G40+H40+I40+J40+K40+L40)*7)*100 -> #DIV/0! | T40: =SUM(O40:S40) -> 0 | U40: =((((O40*1.5+(P40*3.5)+(Q40*5.5)+(R40*7.5)+(S40*12)))/3)/((F40+G40+H40+I40+J40+K40+L40)*7))*100 -> #DIV/0! | V40: =C40+D40-T40 -> 0
...

Sheet พย
A1: การคิด FTEรายวัน
A2: หอผู้ป่วยทารกวิกฤติประจำเดือนพฤศจิกายน.พ.ศ.2567
A3: NN ผู้ป่วยต่อคน | B3: 4.5 | C3: สัดส่วนตามเวร | E3: N | I3: D | M3: E | O3: ค่าเวร | Q3: =((F103+F105)*240)+((G103+G105)*180) -> #REF! | S3: บาท
E4: 0.25 | I4: 0.4 | M4: 0.35 | O4: ค่าOT | Q4: =((I103+L103+I104+L104+I105+L105)*660)+((J103+J105+J104)*530) -> 15180 | S4: บาท
A5: จำนวนพยาบาลมีจริงเดือนนี้ | C5: 15 | E5: คน | F5: จำนวนวันราชการเดือนนี้ | M5: 21 | N5: วัน
A6: จำนวนพยาบาลตามFTE | C6: =((C106*12)/(M5*7)+((D106*12)/(M5*7))) -> 29.496599 | E6: คน | F6: ขาดเกิน | I6: =C5-C6 -> -14.496599 | L6: คน | M6: product | N6: =((((C106*4.5)+(D106*12))/((F106+G106+H106+I106+J106+K106+L106)*7)))*100 -> #REF! | O6: product ตามประเภท | R6: =U106 -> #REF!
A7: วันที่ | B7: เวร | C7: sick new born | D7: NICU | E7: FTE | F7: ขึ้นตามตารางเวร | L7: OT เสริม | M7: -ขาด/+เกิน | N7: product | O7: ประเภทผู้ป่วย | T7: รวม | U7: product ตามประเภท
F8: ไม่ใช่ OT | I8: OT | O8: 1 | P8: 2 | Q8: 3 | R8: 4 | S8: 5
F9: RN | G9: TN | H9: PN | I9: RN | J9: TN | K9: PN
A10: 1 | B10: N | C10: 9 | D10: 4 | E10: =((($B$3*C10)+(12*D10))*$E$4)/7 -> 3.1607143 | F10: 3 | G10: 0 | H10: 0 | I10: 0 | J10: 0 | K10: 0 | M10: =(F10+G10+H10+L10)-E10 -> -0.16071429 | N10: =(((C10*4.5)+(12*D10))*$E$4)/((F10+G10+H10+I10+J10+K10+L10)*7)*100 -> 105.35714 | O10: 0 | P10: 0 | Q10: 10 | R10: 1 | S10: 2 | T10: =SUM(O10:S10) -> 13 | U10: =((((O10*1.5+(P10*3.5)+(Q10*5.5)+(R10*7.5)+(S10*12)))/3)/((F10+G10+H10+I10+J10+K10+L10)*7))*100 -> 137.30159 | V10: =C10+D10-T10 -> 0
B11: D | C11: 9 | D11: 4 | E11: =((($B$3*C11)+(12*D11))*$E$4)/7 -> 3.1607143 | F11: 3 | G11: 0 | H11: 0 | I11: 0 | J11: 0 | K11: 0 | M11: =(F11+G11+H11+L11)-E11 -> -0.16071429 | N11: =(((C11*4.5)+(12*D11))*$E$4)/((F11+G11+H11+I11+J11+K11+L11)*7)*100 -> 105.35714 | O11: 0 | P11: 1 | Q11: 7 | R11: 1 | S11: 2 | T11: =SUM(O11:S11) -> 11 | U11: =((((O11*1.5+(P11*3.5)+(Q11*5.5)+(R11*7.5)+(S11*12)))/3)/((F11+G11+H11+I11+J11+K11+L11)*7))*100 -> 116.66667 | V11: =C11+D11-T11 -> 2
B12: E | C12: 8 | D12: 4 | E12: =((($B$3*C12)+(12*D12))*$E$4)/7 -> 3 | F12: 2 | G12: 0 | H12: 0 | I12: 1 | J12: 0 | K12: 0 | M12: =(F12+G12+H12+L12)-E12 -> -1 | N12: =(((C12*4.5)+(12*D12))*$E$4)/((F12+G12+H12+I12+J12+K12+L12)*7)*100 -> 100 | O12: 0 | P12: 0 | Q12: 9 | R12: 1 | S12: 2 | T12: =SUM(O12:S12) -> 12 | U12: =((((O12*1.5+(P12*3.5)+(Q12*5.5)+(R12*7.5)+(S12*12)))/3)/((F12+G12+H12+I12+J12+K12+L12)*7))*100 -> 128.57143 | V12: =C12+D12-T12 -> 0
A13: 2 | B13: N | C13: 9 | D13: 4 | E13: =((($B$3*C13)+(12*D13))*$E$4)/7 -> 3.1607143 | F13: 3 | G13: 0 | H13: 0 | I13: 0 | J13: 0 | K13: 0 | M13: =(F13+G13+H13+L13)-E13 -> -0.16071429 | N13: =(((C13*4.5)+(12*D13))*$E$4)/((F13+G13+H13+I13+J13+K13+L13)*7)*100 -> 105.35714 | O13: 0 | P13: 0 | Q13: 10 | R13: 1 | S13: 2 | T13: =SUM(O13:S13) -> 13 | U13: =((((O13*1.5+(P13*3.5)+(Q13*5.5)+(R13*7.5)+(S13*12)))/3)/((F13+G13+H13+I13+J13+K13+L13)*7))*100 -> 137.30159 | V13: =C13+D13-T13 -> 0
B14: D | C14: 8 | D14: 4 | E14: =((($B$3*C14)+(12*D14))*$E$4)/7 -> 3 | F14: 1 | G14: 0 | H14: 0 | I14: 2 | J14: 0 | K14: 0 | M14: =(F14+G14+H14+L14)-E14 -> -2 | N14: =(((C14*4.5)+(12*D14))*$E$4)/((F14+G14+H14+I14+J14+K14+L14)*7)*100 -> 100 | O14: 0 | P14: 1 | Q14: 8 | R14: 0 | S14: 3 | T14: =SUM(O14:S14) -> 12 | U14: =((((O14*1.5+(P14*3.5)+(Q14*5.5)+(R14*7.5)+(S14*12)))/3)/((F14+G14+H14+I14+J14+K14+L14)*7))*100 -> 132.53968 | V14: =C14+D14-T14 -> 0
B15: E | C15: 8 | D15: 4 | E15: =((($B$3*C15)+(12*D15))*$E$4)/7 -> 3 | F15: 3 | G15: 0 | H15: 0 | I15: 0 | J15: 0 | K15: 0 | M15: =(F14+G14+H14+L14)-E14 -> -2 | N15: =(((C15*4.5)+(12*D15))*$E$4)/((F15+G15+H15+I15+J15+K15+L15)*7)*100 -> 100 | O15: 0 | P15: 0 | Q15: 9 | R15: 0 | S15: 3 | T15: =SUM(O15:S15) -> 12 | U15: =((((O15*1.5+(P15*3.5)+(Q15*5.5)+(R15*7.5)+(S15*12)))/3)/((F15+G15+H15+I15+J15+K15+L15)*7))*100 -> 135.71429 | V15: =C15+D15-T15 -> 0
A16: 3 | B16: N | C16: 8 | D16: 4 | E16: =((($B$3*C16)+(12*D16))*$E$4)/7 -> 3 | F16: 2 | G16: 0 | H16: 0 | I16: 1 | J16: 0 | K16: 0 | M16: =(F16+G16+H16+L16)-E16 -> -1 | N16: =(((C16*4.5)+(12*D16))*$E$4)/((F16+G16+H16+I16+J16+K16+L16)*7)*100 -> 100 | O16: 0 | P16: 0 | Q16: 9 | R16: 0 | S16: 3 | T16: =SUM(O16:S16) -> 12 | U16: =((((O16*1.5+(P16*3.5)+(Q16*5.5)+(R16*7.5)+(S16*12)))/3)/((F16+G16+H16+I16+J16+K16+L16)*7))*100 -> 135.71429 | V16: =C16+D16-T16 -> 0
B17: D | C17: 8 | D17: 5 | E17: =((($B$3*C17)+(12*D17))*$E$4)/7 -> 3.4285714 | F17: 3 | G17: 0 | H17: 0 | I17: 1 | J17: 0 | K17: 0 | M17: =(F17+G17+H17+L17)-E17 -> -0.42857143 | N17: =(((C17*4.5)+(12*D17))*$E$4)/((F17+G17+H17+I17+J17+K17+L17)*7)*100 -> 85.714286 | O17: 0 | P17: 2 | Q17: 7 | R17: 0 | S17: 4 | T17: =SUM(O17:S17) -> 13 | U17: =((((O17*1.5+(P17*3.5)+(Q17*5.5)+(R17*7.5)+(S17*12)))/3)/((F17+G17+H17+I17+J17+K17+L17)*7))*100 -> 111.30952 | V17: =C17+D17-T17 -> 0
B18: E | C18: 6 | D18: 5 | E18: =((($B$3*C18)+(12*D18))*$E$4)/7 -> 3.1071429 | F18: 2 | G18: 0 | H18: 1 | I18: 1 | J18: 0 | K18: 0 | M18: =(F18+G18+H18+L18)-E18 -> -0.10714286 | N18: =(((C18*4.5)+(12*D18))*$E$4)/((F18+G18+H18+I18+J18+K18+L18)*7)*100 -> 77.678571 | O18: 0 | P18: 0 | Q18: 7 | R18: 0 | S18: 4 | T18: =SUM(O18:S18) -> 11 | U18: =((((O18*1.5+(P18*3.5)+(Q18*5.5)+(R18*7.5)+(S18*12)))/3)/((F18+G18+H18+I18+J18+K18+L18)*7))*100 -> 102.97619 | V18: =C18+D18-T18 -> 0
A19: 4 | B19: N | C19: 6 | D19: 5 | E19: =((($B$3*C19)+(12*D19))*$E$4)/7 -> 3.1071429 | F19: 3 | G19: 0 | H19: 0 | I19: 0 | J19: 0 | K19: 0 | M19: =(F19+G19+H19+L19)-E19 -> -0.10714286 | N19: =(((C19*4.5)+(12*D19))*$E$4)/((F19+G19+H19+I19+J19+K19+L19)*7)*100 -> 103.57143 | O19: 0 | P19: 0 | Q19: 7 | R19: 0 | S19: 4 | T19: =SUM(O19:S19) -> 11 | U19: =((((O19*1.5+(P19*3.5)+(Q19*5.5)+(R19*7.5)+(S19*12)))/3)/((F19+G19+H19+I19+J19+K19+L19)*7))*100 -> 137.30159 | V19: =C19+D19-T19 -> 0
B20: D | C20: 7 | D20: 5 | E20: =((($B$3*C20)+(12*D20))*$E$4)/7 -> 3.2678571 | F20: 2 | G20: 0 | H20: 0 | I20: 1 | J20: 0 | K20: 1 | M20: =(F20+G20+H20+L20)-E20 -> -1.2678571 | N20: =(((C20*4.5)+(12*D20))*$E$4)/((F20+G20+H20+I20+J20+K20+L20)*7)*100 -> 81.696429 | O20: 0 | P20: 3 | Q20: 5 | R20: 0 | S20: 4 | T20: =SUM(O20:S20) -> 12 | U20: =((((O20*1.5+(P20*3.5)+(Q20*5.5)+(R20*7.5)+(S20*12)))/3)/((F20+G20+H20+I20+J20+K20+L20)*7))*100 -> 102.38095 | V20: =C20+D20-T20 -> 0
B21: E | C21: 3 | D21: 5 | E21: =((($B$3*C21)+(12*D21))*$E$4)/7 -> 2.625 | F21: 3 | G21: 0 | H21: 0 | I21: 0 | J21: 0 | K21: 0 | M21: =(F21+G21+H21+L21)-E21 -> 0.375 | N21: =(((C21*4.5)+(12*D21))*$E$4)/((F21+G21+H21+I21+J21+K21+L21)*7)*100 -> 87.5 | O21: 0 | P21: 0 | Q21: 4 | R21: 1 | S21: 3 | T21: =SUM(O21:S21) -> 8 | U21: =((((O21*1.5+(P21*3.5)+(Q21*5.5)+(R21*7.5)+(S21*12)))/3)/((F21+G21+H21+I21+J21+K21+L21)*7))*100 -> 103.96825 | V21: =C21+D21-T21 -> 0
A22: 5 | B22: N | C22: 3 | D22: 5 | E22: =((($B$3*C22)+(12*D22))*$E$4)/7 -> 2.625 | F22: 3 | G22: 0 | H22: 0 | I22: 0 | J22: 0 | K22: 0 | M22: =(F22+G22+H22+L22)-E22 -> 0.375 | N22: =(((C22*4.5)+(12*D22))*$E$4)/((F22+G22+H22+I22+J22+K22+L22)*7)*100 -> 87.5 | O22: 0 | P22: 0 | Q22: 4 | R22: 1 | S22: 3 | T22: =SUM(O22:S22) -> 8 | U22: =((((O22*1.5+(P22*3.5)+(Q22*5.5)+(R22*7.5)+(S22*12)))/3)/((F22+G22+H22+I22+J22+K22+L22)*7))*100 -> 103.96825 | V22: =C22+D22-T22 -> 0
B23: D | C23: 4 | D23: 5 | E23: =((($B$3*C23)+(12*D23))*$E$4)/7 -> 2.7857143 | F23: 3 | G23: 0 | H23: 1 | I23: 0 | J23: 0 | K23: 0 | M23: =(F23+G23+H23+L23)-E23 -> 1.2142857 | N23: =(((C23*4.5)+(12*D23))*$E$4)/((F23+G23+H23+I23+J23+K23+L23)*7)*100 -> 69.642857 | O23: 0 | P23: 2 | Q23: 3 | R23: 1 | S23: 3 | T23: =SUM(O23:S23) -> 9 | U23: =((((O23*1.5+(P23*3.5)+(Q23*5.5)+(R23*7.5)+(S23*12)))/3)/((F23+G23+H23+I23+J23+K23+L23)*7))*100 -> 79.761905 | V23: =C23+D23-T23 -> 0
B24: E | C24: 2 | D24: 5 | E24: =((($B$3*C24)+(12*D24))*$E$4)/7 -> 2.4642857 | F24: 3 | G24: 0 | H24: 0 | I24: 0 | J24: 0 | K24: 0 | M24: =(F24+G24+H24+L24)-E24 -> 0.53571429 | N24: =(((C24*4.5)+(12*D24))*$E$4)/((F24+G24+H24+I24+J24+K24+L24)*7)*100 -> 82.142857 | O24: 0 | P24: 0 | Q24: 3 | R24: 2 | S24: 2 | T24: =SUM(O24:S24) -> 7 | U24: =((((O24*1.5+(P24*3.5)+(Q24*5.5)+(R24*7.5)+(S24*12)))/3)/((F24+G24+H24+I24+J24+K24+L24)*7))*100 -> 88.095238 | V24: =C24+D24-T24 -> 0
A25: 6 | B25: N | C25: 2 | D25: 5 | E25: =((($B$3*C25)+(12*D25))*$E$4)/7 -> 2.4642857 | F25: 3 | G25: 0 | H25: 0 | I25: 0 | J25: 0 | K25: 0 | M25: =(F25+G25+H25+L25)-E25 -> 0.53571429 | N25: =(((C25*4.5)+(12*D25))*$E$4)/((F25+G25+H25+I25+J25+K25+L25)*7)*100 -> 82.142857 | O25: 0 | P25: 0 | Q25: 3 | R25: 2 | S25: 2 | T25: =SUM(O25:S25) -> 7 | U25: =((((O25*1.5+(P25*3.5)+(Q25*5.5)+(R25*7.5)+(S25*12)))/3)/((F25+G25+H25+I25+J25+K25+L25)*7))*100 -> 88.095238 | V25: =C25+D25-T25 -> 0
B26: D | C26: 6 | D26: 4 | E26: =((($B$3*C26)+(12*D26))*$E$4)/7 -> 2.6785714 | F26: 4 | G26: 0 | H26: 1 | I26: 0 | J26: 0 | K26: 0 | M26: =(F26+G26+H26+L26)-E26 -> 2.3214286 | N26: =(((C26*4.5)+(12*D26))*$E$4)/((F26+G26+H26+I26+J26+K26+L26)*7)*100 -> 53.571429 | O26: 0 | P26: 1 | Q26: 5 | R26: 2 | S26: 2 | T26: =SUM(O26:S26) -> 10 | U26: =((((O26*1.5+(P26*3.5)+(Q26*5.5)+(R26*7.5)+(S26*12)))/3)/((F26+G26+H26+I26+J26+K26+L26)*7))*100 -> 66.666667 | V26: =C26+D26-T26 -> 0
B27: E | C27: 4 | D27: 4 | E27: =((($B$3*C27)+(12*D27))*$E$4)/7 -> 2.3571429 | F27: 3 | G27: 0 | H27: 0 | I27: 0 | J27: 0 | K27: 1 | M27: =(F27+G27+H27+L27)-E27 -> 0.64285714 | N27: =(((C27*4.5)+(12*D27))*$E$4)/((F27+G27+H27+I27+J27+K27+L27)*7)*100 -> 58.928571 | O27: 0 | P27: 0 | Q27: 5 | R27: 1 | S27: 2 | T27: =SUM(O27:S27) -> 8 | U27: =((((O27*1.5+(P27*3.5)+(Q27*5.5)+(R27*7.5)+(S27*12)))/3)/((F27+G27+H27+I27+J27+K27+L27)*7))*100 -> 70.238095 | V27: =C27+D27-T27 -> 0
A28: 7 | B28: N | C28: 4 | D28: 4 | E28: =((($B$3*C28)+(12*D28))*$E$4)/7 -> 2.3571429 | F28: 1 | G28: 0 | H28: 0 | I28: 2 | J28: 0 | K28: 0 | M28: =(F28+G28+H28+L28)-E28 -> -1.3571429 | N28: =(((C28*4.5)+(12*D28))*$E$4)/((F28+G28+H28+I28+J28+K28+L28)*7)*100 -> 78.571429 | O28: 0 | P28: 0 | Q28: 5 | R28: 1 | S28: 2 | T28: =SUM(O28:S28) -> 8 | U28: =((((O28*1.5+(P28*3.5)+(Q28*5.5)+(R28*7.5)+(S28*12)))/3)/((F28+G28+H28+I28+J28+K28+L28)*7))*100 -> 93.650794 | V28: =C28+D28-T28 -> 0
B29: D | C29: 4 | D29: 4 | E29: =((($B$3*C29)+(12*D29))*$E$4)/7 -> 2.3571429 | F29: 3 | G29: 0 | H29: 0 | I29: 1 | J29: 0 | K29: 0 | M29: =(F29+G29+H29+L29)-E29 -> 0.64285714 | N29: =(((C29*4.5)+(12*D29))*$E$4)/((F29+G29+H29+I29+J29+K29+L29)*7)*100 -> 58.928571 | O29: 0 | P29: 1 | Q29: 3 | R29: 2 | S29: 2 | T29: =SUM(O29:S29) -> 8 | U29: =((((O29*1.5+(P29*3.5)+(Q29*5.5)+(R29*7.5)+(S29*12)))/3)/((F29+G29+H29+I29+J29+K29+L29)*7))*100 -> 70.238095 | V29: =C29+D29-T29 -> 0
B30: E | C30: 5 | D30: 5 | E30: =((($B$3*C30)+(12*D30))*$E$4)/7 -> 2.9464286 | F30: 2 | G30: 0 | H30: 0 | I30: 1 | J30: 0 | K30: 0 | M30: =(F30+G30+H30+L30)-E30 -> -0.94642857 | N30: =(((C30*4.5)+(12*D30))*$E$4)/((F30+G30+H30+I30+J30+K30+L30)*7)*100 -> 98.214286 | O30: 0 | P30: 0 | Q30: 5 | R30: 3 | S30: 2 | T30: =SUM(O30:S30) -> 10 | U30: =((((O30*1.5+(P30*3.5)+(Q30*5.5)+(R30*7.5)+(S30*12)))/3)/((F30+G30+H30+I30+J30+K30+L30)*7))*100 -> 117.46032 | V30: =C30+D30-T30 -> 0
A31: 8 | B31: N | C31: 5 | D31: 5 | E31: =((($B$3*C31)+(12*D31))*$E$4)/7 -> 2.9464286 | F31: 3 | G31: 0 | H31: 0 | I31: 0 | J31: 0 | K31: 0 | M31: =(F31+G31+H31+L31)-E31 -> 0.053571429 | N31: =(((C31*4.5)+(12*D31))*$E$4)/((F31+G31+H31+I31+J31+K31+L31)*7)*100 -> 98.214286 | O31: 0 | P31: 0 | Q31: 5 | R31: 3 | S31: 2 | T31: =SUM(O31:S31) -> 10 | U31: =((((O31*1.5+(P31*3.5)+(Q31*5.5)+(R31*7.5)+(S31*12)))/3)/((F31+G31+H31+I31+J31+K31+L31)*7))*100 -> 117.46032 | V31: =C31+D31-T31 -> 0
B32: D | C32: 7 | D32: 5 | E32: =((($B$3*C32)+(12*D32))*$E$4)/7 -> 3.2678571 | F32: 4 | G32: 0 | H32: 1 | I32: 0 | J32: 0 | K32: 0 | L32: 0 | M32: =(F32+G32+H32+L32)-E32 -> 1.7321429 | N32: =(((C32*4.5)+(12*D32))*$E$4)/((F32+G32+H32+I32+J32+K32+L32)*7)*100 -> 65.357143 | O32: 0 | P32: 0 | Q32: 7 | R32: 3 | S32: 2 | T32: =SUM(O32:S32) -> 12 | U32: =((((O32*1.5+(P32*3.5)+(Q32*5.5)+(R32*7.5)+(S32*12)))/3)/((F32+G32+H32+I32+J32+K32+L32)*7))*100 -> 80.952381 | V32: =C32+D32-T32 -> 0
B33: E | C33: 7 | D33: 5 | E33: =((($B$3*C33)+(12*D33))*$E$4)/7 -> 3.2678571 | F33: 3 | G33: 0 | H33: 1 | I33: 0 | J33: 0 | K33: 0 | M33: =(F33+G33+H33+L33)-E33 -> 0.73214286 | N33: =(((C33*4.5)+(12*D33))*$E$4)/((F33+G33+H33+I33+J33+K33+L33)*7)*100 -> 81.696429 | O33: 0 | P33: 0 | Q33: 7 | R33: 3 | S33: 2 | T33: =SUM(O33:S33) -> 12 | U33: =((((O33*1.5+(P33*3.5)+(Q33*5.5)+(R33*7.5)+(S33*12)))/3)/((F33+G33+H33+I33+J33+K33+L33)*7))*100 -> 101.19048 | V33: =C33+D33-T33 -> 0
A34: 9 | B34: N | C34: 6 | D34: 5 | E34: =((($B$3*C34)+(12*D34))*$E$4)/7 -> 3.1071429 | F34: 3 | G34: 0 | H34: 0 | I34: 0 | J34: 0 | K34: 0 | M34: =(F34+G34+H34+L34)-E34 -> -0.10714286 | N34: =(((C34*4.5)+(12*D34))*$E$4)/((F34+G34+H34+I34+J34+K34+L34)*7)*100 -> 103.57143 | O34: 0 | P34: 0 | Q34: 7 | R34: 2 | S34: 2 | T34: =SUM(O34:S34) -> 11 | U34: =((((O34*1.5+(P34*3.5)+(Q34*5.5)+(R34*7.5)+(S34*12)))/3)/((F34+G34+H34+I34+J34+K34+L34)*7))*100 -> 123.01587 | V34: =C34+D34-T34 -> 0
B35: D | C35: 6 | D35: 6 | E35: =((($B$3*C35)+(12*D35))*$E$4)/7 -> 3.5357143 | F35: 1 | G35: 0 | H35: 1 | I35: 2 | J35: 0 | K35: 0 | M35: =(F35+G35+H35+L35)-E35 -> -1.5357143 | N35: =(((C35*4.5)+(12*D35))*$E$4)/((F35+G35+H35+I35+J35+K35+L35)*7)*100 -> 88.392857 | O35: 0 | P35: 0 | Q35: 8 | R35: 1 | S35: 3 | T35: =SUM(O35:S35) -> 12 | U35: =((((O35*1.5+(P35*3.5)+(Q35*5.5)+(R35*7.5)+(S35*12)))/3)/((F35+G35+H35+I35+J35+K35+L35)*7))*100 -> 104.16667 | V35: =C35+D35-T35 -> 0
B36: E | C36: 7 | D36: 6 | E36: =((($B$3*C36)+(12*D36))*$E$4)/7 -> 3.6964286 | F36: 3 | G36: 0 | H36: 0 | I36: 0 | J36: 0 | K36: 0 | M36: =(F36+G36+H36+L36)-E36 -> -0.69642857 | N36: =(((C36*4.5)+(12*D36))*$E$4)/((F36+G36+H36+I36+J36+K36+L36)*7)*100 -> 123.21429 | O36: 0 | P36: 0 | Q36: 8 | R36: 2 | S36: 3 | T36: =SUM(O36:S36) -> 13 | U36: =((((O36*1.5+(P36*3.5)+(Q36*5.5)+(R36*7.5)+(S36*12)))/3)/((F36+G36+H36+I36+J36+K36+L36)*7))*100 -> 150.79365 | V36: =C36+D36-T36 -> 0
A37: 10 | B37: N | C37: 7 | D37: 6 | E37: =((($B$3*C37)+(12*D37))*$E$4)/7 -> 3.6964286 | F37: 3 | G37: 0 | H37: 0 | I37: 0 | J37: 0 | K37: 0 | M37: =(F37+G37+H37+L37)-E37 -> -0.69642857 | N37: =(((C37*4.5)+(12*D37))*$E$4)/((F37+G37+H37+I37+J37+K37+L37)*7)*100 -> 123.21429 | O37: 0 | P37: 0 | Q37: 8 | R37: 2 | S37: 3 | T37: =SUM(O37:S37) -> 13 | U37: =((((O37*1.5+(P37*3.5)+(Q37*5.5)+(R37*7.5)+(S37*12)))/3)/((F37+G37+H37+I37+J37+K37+L37)*7))*100 -> 150.79365 | V37: =C37+D37-T37 -> 0
B38: D | C38: 9 | D38: 6 | E38: =((($B$3*C38)+(12*D38))*$E$4)/7 -> 4.0178571 | F38: 3 | G38: 0 | H38: 0 | I38: 0 | J38: 0 | K38: 0 | M38: =(F38+G38+H38+L38)-E38 -> -1.0178571 | N38: =(((C38*4.5)+(12*D38))*$E$4)/((F38+G38+H38+I38+J38+K38+L38)*7)*100 -> 133.92857 | O38: 0 | P38: 0 | Q38: 10 | R38: 2 | S38: 3 | T38: =SUM(O38:S38) -> 15 | U38: =((((O38*1.5+(P38*3.5)+(Q38*5.5)+(R38*7.5)+(S38*12)))/3)/((F38+G38+H38+I38+J38+K38+L38)*7))*100 -> 168.25397 | V38: =C38+D38-T38 -> 0
B39: E | C39: 9 | D39: 6 | E39: =((($B$3*C39)+(12*D39))*$E$4)/7 -> 4.0178571 | F39: 2 | G39: 0 | H39: 0 | I39: 1 | J39: 0 | K39: 1 | M39: =(F39+G39+H39+L39)-E39 -> -2.0178571 | N39: =(((C39*4.5)+(12*D39))*$E$4)/((F39+G39+H39+I39+J39+K39+L39)*7)*100 -> 100.44643 | O39: 0 | P39: 0 | Q39: 10 | R39: 3 | S39: 2 | T39: =SUM(O39:S39) -> 15 | U39: =((((O39*1.5+(P39*3.5)+(Q39*5.5)+(R39*7.5)+(S39*12)))/3)/((F39+G39+H39+I39+J39+K39+L39)*7))*100 -> 120.83333 | V39: =C39+D39-T39 -> 0
A40: 11 | B40: N | C40: 8 | D40: 6 | E40: =((($B$3*C40)+(12*D40))*$E$4)/7 -> 3.8571429 | F40: 3 | G40: 0 | H40: 0 | I40: 0 | J40: 0 | K40: 0 | M40: =(F40+G40+H40+L40)-E40 -> -0.85714286 | N40: =(((C40*4.5)+(12*D40))*$E$4)/((F40+G40+H40+I40+J40+K40+L40)*7)*100 -> 128.57143 | O40: 0 | P40: 0 | Q40: 10 | R40: 2 | S40: 2 | T40: =SUM(O40:S40) -> 14 | U40: =((((O40*1.5+(P40*3.5)+(Q40*5.5)+(R40*7.5)+(S40*12)))/3)/((F40+G40+H40+I40+J40+K40+L40)*7))*100 -> 149.20635 | V40: =C40+D40-T40 -> 0
...

Sheet ธค
A1: การคิด FTEรายวัน
A2: หอผู้ป่วย…ทารกวิกฤต…...ประจำเดือน.....ธันวาคม.........พ.ศ....2567.............
A3: NN ผู้ป่วยต่อคน | B3: 4.5 | C3: สัดส่วนตามเวร | E3: N | I3: D | M3: E | O3: ค่าเวร | Q3: =((F103+F105)*240)+((G103+G105)*180) -> 41040 | S3: บาท
E4: 0.25 | I4: 0.4 | M4: 0.35 | O4: ค่าOT | Q4: =((I103+L103+I104+L104+I105+L105)*660)+((J103+J105+J104)*530) -> 18480 | S4: บาท
A5: จำนวนพยาบาลมีจริงเดือนนี้ | C5: 15 | E5: คน | F5: จำนวนวันราชการเดือนนี้ | M5: 18 | N5: วัน
A6: จำนวนพยาบาลตามFTE | C6: =((C106*12)/(M5*7)+((D106*12)/(M5*7))) -> 34.571429 | E6: คน | F6: ขาดเกิน | I6: =C5-C6 -> -19.571429 | L6: คน | M6: product | N6: =((((C106*4.5)+(D106*12))/((F106+G106+H106+I106+J106+K106+L106)*7)))*100 -> 131.85268 | O6: product ตามประเภท | R6: =U106 -> 42.244544
A7: วันที่ | B7: เวร | C7: sick new born | D7: NICU | E7: FTE | F7: ขึ้นตามตารางเวร | L7: OT เสริม | M7: -ขาด/+เกิน | N7: product | O7: ประเภทผู้ป่วย | T7: รวม | U7: product ตามประเภท
F8: ไม่ใช่ OT | I8: OT | O8: 1 | P8: 2 | Q8: 3 | R8: 4 | S8: 5
F9: RN | G9: TN | H9: PN | I9: RN | J9: TN | K9: PN
A10: 1 | B10: N | C10: 9 | D10: 4 | E10: =((($B$3*C10)+(12*D10))*$E$4)/7 -> 3.1607143 | F10: 2 | G10: 0 | H10: 0 | I10: 1 | J10: 0 | K10: 0 | M10: =(F10+G10+H10+L10)-E10 -> -1.1607143 | N10: =(((C10*4.5)+(12*D10))*$E$4)/((F10+G10+H10+I10+J10+K10+L10)*7)*100 -> 105.35714 | O10: 0 | P10: 0 | Q10: 10 | R10: 0 | S10: 3 | T10: =SUM(O10:S10) -> 13 | U10: =((((O10*1.5+(P10*3.5)+(Q10*5.5)+(R10*7.5)+(S10*12)))/3)/((F10+G10+H10+I10+J10+K10+L10)*7))*100 -> 144.44444 | V10: =C10+D10-T10 -> 0
B11: D | C11: 13 | D11: 4 | E11: =((($B$3*C11)+(12*D11))*$E$4)/7 -> 3.8035714 | F11: 3 | G11: 0 | H11: 0 | I11: 0 | J11: 0 | K11: 1 | M11: =(F11+G11+H11+L11)-E11 -> -0.80357143 | N11: =(((C11*4.5)+(12*D11))*$E$4)/((F11+G11+H11+I11+J11+K11+L11)*7)*100 -> 95.089286 | O11: 0 | P11: 0 | Q11: 13 | R11: 0 | S11: 4 | T11: =SUM(O11:S11) -> 17 | U11: =((((O11*1.5+(P11*3.5)+(Q11*5.5)+(R11*7.5)+(S11*12)))/3)/((F11+G11+H11+I11+J11+K11+L11)*7))*100 -> 142.2619 | V11: =C11+D11-T11 -> 0
B12: E | C12: 11 | D12: 4 | E12: =((($B$3*C12)+(12*D12))*$E$4)/7 -> 3.4821429 | F12: 3 | G12: 0 | H12: 0 | I12: 0 | J12: 0 | K12: 0 | M12: =(F12+G12+H12+L12)-E12 -> -0.48214286 | N12: =(((C12*4.5)+(12*D12))*$E$4)/((F12+G12+H12+I12+J12+K12+L12)*7)*100 -> 116.07143 | O12: 0 | P12: 0 | Q12: 11 | R12: 0 | S12: 4 | T12: =SUM(O12:S12) -> 15 | U12: =((((O12*1.5+(P12*3.5)+(Q12*5.5)+(R12*7.5)+(S12*12)))/3)/((F12+G12+H12+I12+J12+K12+L12)*7))*100 -> 172.22222 | V12: =C12+D12-T12 -> 0
A13: 2 | B13: N | C13: 11 | D13: 4 | E13: =((($B$3*C13)+(12*D13))*$E$4)/7 -> 3.4821429 | F13: 3 | G13: 0 | H13: 0 | I13: 0 | J13: 0 | K13: 0 | M13: =(F13+G13+H13+L13)-E13 -> -0.48214286 | N13: =(((C13*4.5)+(12*D13))*$E$4)/((F13+G13+H13+I13+J13+K13+L13)*7)*100 -> 116.07143 | O13: 0 | P13: 0 | Q13: 11 | R13: 0 | S13: 4 | T13: =SUM(O13:S13) -> 15 | U13: =((((O13*1.5+(P13*3.5)+(Q13*5.5)+(R13*7.5)+(S13*12)))/3)/((F13+G13+H13+I13+J13+K13+L13)*7))*100 -> 172.22222 | V13: =C13+D13-T13 -> 0
B14: D | C14: 10 | D14: 4 | E14: =((($B$3*C14)+(12*D14))*$E$4)/7 -> 3.3214286 | F14: 2 | G14: 0 | H14: 0 | I14: 1 | J14: 0 | K14: 1 | M14: =(F14+G14+H14+L14)-E14 -> -1.3214286 | N14: =(((C14*4.5)+(12*D14))*$E$4)/((F14+G14+H14+I14+J14+K14+L14)*7)*100 -> 83.035714 | O14: 0 | P14: 2 | Q14: 8 | R14: 0 | S14: 4 | T14: =SUM(O14:S14) -> 14 | U14: =((((O14*1.5+(P14*3.5)+(Q14*5.5)+(R14*7.5)+(S14*12)))/3)/((F14+G14+H14+I14+J14+K14+L14)*7))*100 -> 117.85714 | V14: =C14+D14-T14 -> 0
B15: E | C15: 10 | D15: 4 | E15: =((($B$3*C15)+(12*D15))*$E$4)/7 -> 3.3214286 | F15: 3 | G15: 0 | H15: 0 | I15: 0 | J15: 0 | K15: 0 | M15: =(F15+G15+H15+L15)-E15 -> -0.32142857 | N15: =(((C15*4.5)+(12*D15))*$E$4)/((F15+G15+H15+I15+J15+K15+L15)*7)*100 -> 110.71429 | O15: 0 | P15: 0 | Q15: 10 | R15: 1 | S15: 3 | T15: =SUM(O15:S15) -> 14 | U15: =((((O15*1.5+(P15*3.5)+(Q15*5.5)+(R15*7.5)+(S15*12)))/3)/((F15+G15+H15+I15+J15+K15+L15)*7))*100 -> 156.34921 | V15: =C15+D15-T15 -> 0
A16: 3 | B16: N | C16: 10 | D16: 4 | E16: =((($B$3*C16)+(12*D16))*$E$4)/7 -> 3.3214286 | F16: 3 | G16: 0 | H16: 0 | I16: 0 | J16: 0 | K16: 0 | M16: =(F16+G16+H16+L16)-E16 -> -0.32142857 | N16: =(((C16*4.5)+(12*D16))*$E$4)/((F16+G16+H16+I16+J16+K16+L16)*7)*100 -> 110.71429 | O16: 0 | P16: 0 | Q16: 11 | R16: 1 | S16: 2 | T16: =SUM(O16:S16) -> 14 | U16: =((((O16*1.5+(P16*3.5)+(Q16*5.5)+(R16*7.5)+(S16*12)))/3)/((F16+G16+H16+I16+J16+K16+L16)*7))*100 -> 146.03175 | V16: =C16+D16-T16 -> 0
B17: D | C17: 12 | D17: 5 | E17: =((($B$3*C17)+(12*D17))*$E$4)/7 -> 4.0714286 | F17: 3 | G17: 0 | H17: 0 | I17: 0 | J17: 0 | K17: 1 | M17: =(F17+G17+H17+L17)-E17 -> -1.0714286 | N17: =(((C17*4.5)+(12*D17))*$E$4)/((F17+G17+H17+I17+J17+K17+L17)*7)*100 -> 101.78571 | O17: 0 | P17: 3 | Q17: 10 | R17: 2 | S17: 2 | T17: =SUM(O17:S17) -> 17 | U17: =((((O17*1.5+(P17*3.5)+(Q17*5.5)+(R17*7.5)+(S17*12)))/3)/((F17+G17+H17+I17+J17+K17+L17)*7))*100 -> 124.40476 | V17: =C17+D17-T17 -> 0
B18: E | C18: 8 | D18: 5 | E18: =((($B$3*C18)+(12*D18))*$E$4)/7 -> 3.4285714 | F18: 3 | G18: 0 | H18: 0 | I18: 0 | J18: 0 | K18: 0 | M18: =(F18+G18+H18+L18)-E18 -> -0.42857143 | N18: =(((C18*4.5)+(12*D18))*$E$4)/((F18+G18+H18+I18+J18+K18+L18)*7)*100 -> 114.28571 | O18: 0 | P18: 0 | Q18: 9 | R18: 1 | S18: 3 | T18: =SUM(O18:S18) -> 13 | U18: =((((O18*1.5+(P18*3.5)+(Q18*5.5)+(R18*7.5)+(S18*12)))/3)/((F18+G18+H18+I18+J18+K18+L18)*7))*100 -> 147.61905 | V18: =C18+D18-T18 -> 0
A19: 4 | B19: N | C19: 8 | D19: 5 | E19: =((($B$3*C19)+(12*D19))*$E$4)/7 -> 3.4285714 | F19: 3 | G19: 0 | H19: 0 | I19: 0 | J19: 0 | K19: 0 | M19: =(F19+G19+H19+L19)-E19 -> -0.42857143 | N19: =(((C19*4.5)+(12*D19))*$E$4)/((F19+G19+H19+I19+J19+K19+L19)*7)*100 -> 114.28571 | O19: 0 | P19: 0 | Q19: 9 | R19: 1 | S19: 3 | T19: =SUM(O19:S19) -> 13 | U19: =((((O19*1.5+(P19*3.5)+(Q19*5.5)+(R19*7.5)+(S19*12)))/3)/((F19+G19+H19+I19+J19+K19+L19)*7))*100 -> 147.61905 | V19: =C19+D19-T19 -> 0
B20: D | C20: 10 | D20: 6 | E20: =((($B$3*C20)+(12*D20))*$E$4)/7 -> 4.1785714 | F20: 1 | G20: 0 | H20: 0 | I20: 2 | J20: 0 | K20: 1 | M20: =(F20+G20+H20+L20)-E20 -> -3.1785714 | N20: =(((C20*4.5)+(12*D20))*$E$4)/((F20+G20+H20+I20+J20+K20+L20)*7)*100 -> 104.46429 | O20: 0 | P20: 1 | Q20: 10 | R20: 1 | S20: 5 | T20: =SUM(O20:S20) -> 17 | U20: =((((O20*1.5+(P20*3.5)+(Q20*5.5)+(R20*7.5)+(S20*12)))/3)/((F20+G20+H20+I20+J20+K20+L20)*7))*100 -> 150 | V20: =C20+D20-T20 -> -1
B21: E | C21: 9 | D21: 6 | E21: =((($B$3*C21)+(12*D21))*$E$4)/7 -> 4.0178571 | F21: 3 | G21: 0 | H21: 1 | I21: 0 | J21: 0 | K21: 0 | M21: =(F21+G21+H21+L21)-E21 -> -0.017857143 | N21: =(((C21*4.5)+(12*D21))*$E$4)/((F21+G21+H21+I21+J21+K21+L21)*7)*100 -> 100.44643 | O21: 0 | P21: 0 | Q21: 9 | R21: 1 | S21: 5 | T21: =SUM(O21:S21) -> 15 | U21: =((((O21*1.5+(P21*3.5)+(Q21*5.5)+(R21*7.5)+(S21*12)))/3)/((F21+G21+H21+I21+J21+K21+L21)*7))*100 -> 139.28571 | V21: =C21+D21-T21 -> 0
A22: 5 | B22: N | C22: 9 | D22: 6 | E22: =((($B$3*C22)+(12*D22))*$E$4)/7 -> 4.0178571 | F22: 3 | G22: 0 | H22: 0 | I22: 0 | J22: 0 | K22: 0 | M22: =(F22+G22+H22+L22)-E22 -> -1.0178571 | N22: =(((C22*4.5)+(12*D22))*$E$4)/((F22+G22+H22+I22+J22+K22+L22)*7)*100 -> 133.92857 | O22: 0 | P22: 0 | Q22: 9 | R22: 1 | S22: 5 | T22: =SUM(O22:S22) -> 15 | U22: =((((O22*1.5+(P22*3.5)+(Q22*5.5)+(R22*7.5)+(S22*12)))/3)/((F22+G22+H22+I22+J22+K22+L22)*7))*100 -> 185.71429 | V22: =C22+D22-T22 -> 0
B23: D | C23: 6 | D23: 6 | E23: =((($B$3*C23)+(12*D23))*$E$4)/7 -> 3.5357143 | F23: 3 | G23: 0 | H23: 1 | I23: 0 | J23: 0 | K23: 0 | M23: =(F23+G23+H23+L23)-E23 -> 0.46428571 | N23: =(((C23*4.5)+(12*D23))*$E$4)/((F23+G23+H23+I23+J23+K23+L23)*7)*100 -> 88.392857 | O23: 0 | P23: 3 | Q23: 3 | R23: 1 | S23: 5 | T23: =SUM(O23:S23) -> 12 | U23: =((((O23*1.5+(P23*3.5)+(Q23*5.5)+(R23*7.5)+(S23*12)))/3)/((F23+G23+H23+I23+J23+K23+L23)*7))*100 -> 112.5 | V23: =C23+D23-T23 -> 0
B24: E | C24: 6 | D24: 6 | E24: =((($B$3*C24)+(12*D24))*$E$4)/7 -> 3.5357143 | F24: 3 | G24: 0 | H24: 0 | I24: 0 | J24: 0 | K24: 0 | M24: =(F24+G24+H24+L24)-E24 -> -0.53571429 | N24: =(((C24*4.5)+(12*D24))*$E$4)/((F24+G24+H24+I24+J24+K24+L24)*7)*100 -> 117.85714 | O24: 0 | P24: 0 | Q24: 6 | R24: 1 | S24: 5 | T24: =SUM(O24:S24) -> 12 | U24: =((((O24*1.5+(P24*3.5)+(Q24*5.5)+(R24*7.5)+(S24*12)))/3)/((F24+G24+H24+I24+J24+K24+L24)*7))*100 -> 159.52381 | V24: =C24+D24-T24 -> 0
A25: 6 | B25: N | C25: 6 | D25: 6 | E25: =((($B$3*C25)+(12*D25))*$E$4)/7 -> 3.5357143 | F25: 3 | G25: 0 | H25: 0 | I25: 0 | J25: 0 | K25: 0 | M25: =(F25+G25+H25+L25)-E25 -> -0.53571429 | N25: =(((C25*4.5)+(12*D25))*$E$4)/((F25+G25+H25+I25+J25+K25+L25)*7)*100 -> 117.85714 | O25: 0 | P25: 0 | Q25: 6 | R25: 1 | S25: 5 | T25: =SUM(O25:S25) -> 12 | U25: =((((O25*1.5+(P25*3.5)+(Q25*5.5)+(R25*7.5)+(S25*12)))/3)/((F25+G25+H25+I25+J25+K25+L25)*7))*100 -> 159.52381 | V25: =C25+D25-T25 -> 0
B26: D | C26: 6 | D26: 7 | E26: =((($B$3*C26)+(12*D26))*$E$4)/7 -> 3.9642857 | F26: 3 | G26: 0 | H26: 1 | I26: 0 | J26: 0 | K26: 0 | M26: =(F26+G26+H26+L26)-E26 -> 0.035714286 | N26: =(((C26*4.5)+(12*D26))*$E$4)/((F26+G26+H26+I26+J26+K26+L26)*7)*100 -> 99.107143 | O26: 0 | P26: 2 | Q26: 4 | R26: 3 | S26: 4 | T26: =SUM(O26:S26) -> 13 | U26: =((((O26*1.5+(P26*3.5)+(Q26*5.5)+(R26*7.5)+(S26*12)))/3)/((F26+G26+H26+I26+J26+K26+L26)*7))*100 -> 118.45238 | V26: =C26+D26-T26 -> 0
B27: E | C27: 5 | D27: 6 | E27: =((($B$3*C27)+(12*D27))*$E$4)/7 -> 3.375 | F27: 3 | G27: 0 | H27: 0 | I27: 0 | J27: 0 | K27: 0 | M27: =(F27+G27+H27+L27)-E27 -> -0.375 | N27: =(((C27*4.5)+(12*D27))*$E$4)/((F27+G27+H27+I27+J27+K27+L27)*7)*100 -> 112.5 | O27: 0 | P27: 0 | Q27: 5 | R27: 2 | S27: 4 | T27: =SUM(O27:S27) -> 11 | U27: =((((O27*1.5+(P27*3.5)+(Q27*5.5)+(R27*7.5)+(S27*12)))/3)/((F27+G27+H27+I27+J27+K27+L27)*7))*100 -> 143.65079 | V27: =C27+D27-T27 -> 0
A28: 7 | B28: N | C28: 8 | D28: 7 | E28: =((($B$3*C28)+(12*D28))*$E$4)/7 -> 4.2857143 | F28: 3 | G28: 0 | H28: 0 | I28: 0 | J28: 0 | K28: 0 | M28: =(F28+G28+H28+L28)-E28 -> -1.2857143 | N28: =(((C28*4.5)+(12*D28))*$E$4)/((F28+G28+H28+I28+J28+K28+L28)*7)*100 -> 142.85714 | O28: 0 | P28: 0 | Q28: 7 | R28: 3 | S28: 5 | T28: =SUM(O28:S28) -> 15 | U28: =((((O28*1.5+(P28*3.5)+(Q28*5.5)+(R28*7.5)+(S28*12)))/3)/((F28+G28+H28+I28+J28+K28+L28)*7))*100 -> 192.06349 | V28: =C28+D28-T28 -> 0
B29: D | C29: 8 | D29: 7 | E29: =((($B$3*C29)+(12*D29))*$E$4)/7 -> 4.2857143 | F29: 3 | G29: 0 | H29: 1 | I29: 0 | J29: 0 | K29: 0 | M29: =(F29+G29+H29+L29)-E29 -> -0.28571429 | N29: =(((C29*4.5)+(12*D29))*$E$4)/((F29+G29+H29+I29+J29+K29+L29)*7)*100 -> 107.14286 | O29: 0 | P29: 1 | Q29: 5 | R29: 4 | S29: 5 | T29: =SUM(O29:S29) -> 15 | U29: =((((O29*1.5+(P29*3.5)+(Q29*5.5)+(R29*7.5)+(S29*12)))/3)/((F29+G29+H29+I29+J29+K29+L29)*7))*100 -> 144.04762 | V29: =C29+D29-T29 -> 0
B30: E | C30: 9 | D30: 7 | E30: =((($B$3*C30)+(12*D30))*$E$4)/7 -> 4.4464286 | F30: 3 | G30: 0 | H30: 0 | I30: 0 | J30: 0 | K30: 0 | M30: =(F30+G30+H30+L30)-E30 -> -1.4464286 | N30: =(((C30*4.5)+(12*D30))*$E$4)/((F30+G30+H30+I30+J30+K30+L30)*7)*100 -> 148.21429 | O30: 0 | P30: 0 | Q30: 7 | R30: 4 | S30: 5 | T30: =SUM(O30:S30) -> 16 | U30: =((((O30*1.5+(P30*3.5)+(Q30*5.5)+(R30*7.5)+(S30*12)))/3)/((F30+G30+H30+I30+J30+K30+L30)*7))*100 -> 203.96825 | V30: =C30+D30-T30 -> 0
A31: 8 | B31: N | C31: 9 | D31: 8 | E31: =((($B$3*C31)+(12*D31))*$E$4)/7 -> 4.875 | F31: 3 | G31: 0 | H31: 0 | I31: 0 | J31: 0 | K31: 0 | M31: =(F31+G31+H31+L31)-E31 -> -1.875 | N31: =(((C31*4.5)+(12*D31))*$E$4)/((F31+G31+H31+I31+J31+K31+L31)*7)*100 -> 162.5 | O31: 0 | P31: 0 | Q31: 6 | R31: 5 | S31: 6 | T31: =SUM(O31:S31) -> 17 | U31: =((((O31*1.5+(P31*3.5)+(Q31*5.5)+(R31*7.5)+(S31*12)))/3)/((F31+G31+H31+I31+J31+K31+L31)*7))*100 -> 226.19048 | V31: =C31+D31-T31 -> 0
B32: D | C32: 9 | D32: 8 | E32: =((($B$3*C32)+(12*D32))*$E$4)/7 -> 4.875 | F32: 3 | G32: 0 | H32: 0 | I32: 0 | J32: 0 | K32: 0 | M32: =(F32+G32+H32+L32)-E32 -> -1.875 | N32: =(((C32*4.5)+(12*D32))*$E$4)/((F32+G32+H32+I32+J32+K32+L32)*7)*100 -> 162.5 | O32: 0 | P32: 2 | Q32: 7 | R32: 2 | S32: 6 | T32: =SUM(O32:S32) -> 17 | U32: =((((O32*1.5+(P32*3.5)+(Q32*5.5)+(R32*7.5)+(S32*12)))/3)/((F32+G32+H32+I32+J32+K32+L32)*7))*100 -> 210.31746 | V32: =C32+D32-T32 -> 0
B33: E | C33: 7 | D33: 8 | E33: =((($B$3*C33)+(12*D33))*$E$4)/7 -> 4.5535714 | F33: 3 | G33: 0 | H33: 0 | I33: 0 | J33: 0 | K33: 0 | M33: =(F33+G33+H33+L33)-E33 -> -1.5535714 | N33: =(((C33*4.5)+(12*D33))*$E$4)/((F33+G33+H33+I33+J33+K33+L33)*7)*100 -> 151.78571 | O33: 0 | P33: 0 | Q33: 7 | R33: 2 | S33: 6 | T33: =SUM(O33:S33) -> 15 | U33: =((((O33*1.5+(P33*3.5)+(Q33*5.5)+(R33*7.5)+(S33*12)))/3)/((F33+G33+H33+I33+J33+K33+L33)*7))*100 -> 199.20635 | V33: =C33+D33-T33 -> 0
A34: 9 | B34: N | C34: 9 | D34: 8 | E34: =((($B$3*C34)+(12*D34))*$E$4)/7 -> 4.875 | F34: 3 | G34: 0 | H34: 0 | I34: 0 | J34: 0 | K34: 0 | M34: =(F34+G34+H34+L34)-E34 -> -1.875 | N34: =(((C34*4.5)+(12*D34))*$E$4)/((F34+G34+H34+I34+J34+K34+L34)*7)*100 -> 162.5 | O34: 0 | P34: 0 | Q34: 8 | R34: 3 | S34: 6 | T34: =SUM(O34:S34) -> 17 | U34: =((((O34*1.5+(P34*3.5)+(Q34*5.5)+(R34*7.5)+(S34*12)))/3)/((F34+G34+H34+I34+J34+K34+L34)*7))*100 -> 219.84127 | V34: =C34+D34-T34 -> 0
B35: D | C35: 9 | D35: 8 | E35: =((($B$3*C35)+(12*D35))*$E$4)/7 -> 4.875 | F35: 3 | G35: 0 | H35: 0 | I35: 0 | J35: 0 | K35: 0 | M35: =(F35+G35+H35+L35)-E35 -> -1.875 | N35: =(((C35*4.5)+(12*D35))*$E$4)/((F35+G35+H35+I35+J35+K35+L35)*7)*100 -> 162.5 | O35: 0 | P35: 0 | Q35: 8 | R35: 3 | S35: 6 | T35: =SUM(O35:S35) -> 17 | U35: =((((O35*1.5+(P35*3.5)+(Q35*5.5)+(R35*7.5)+(S35*12)))/3)/((F35+G35+H35+I35+J35+K35+L35)*7))*100 -> 219.84127 | V35: =C35+D35-T35 -> 0
B36: E | C36: 8 | D36: 8 | E36: =((($B$3*C36)+(12*D36))*$E$4)/7 -> 4.7142857 | F36: 3 | G36: 0 | H36: 0 | I36: 0 | J36: 0 | K36: 0 | M36: =(F36+G36+H36+L36)-E36 -> -1.7142857 | N36: =(((C36*4.5)+(12*D36))*$E$4)/((F36+G36+H36+I36+J36+K36+L36)*7)*100 -> 157.14286 | O36: 0 | P36: 0 | Q36: 8 | R36: 2 | S36: 6 | T36: =SUM(O36:S36) -> 16 | U36: =((((O36*1.5+(P36*3.5)+(Q36*5.5)+(R36*7.5)+(S36*12)))/3)/((F36+G36+H36+I36+J36+K36+L36)*7))*100 -> 207.93651 | V36: =C36+D36-T36 -> 0
A37: 10 | B37: N | C37: 8 | D37: 8 | E37: =((($B$3*C37)+(12*D37))*$E$4)/7 -> 4.7142857 | F37: 3 | G37: 0 | H37: 0 | I37: 0 | J37: 0 | K37: 0 | M37: =(F37+G37+H37+L37)-E37 -> -1.7142857 | N37: =(((C37*4.5)+(12*D37))*$E$4)/((F37+G37+H37+I37+J37+K37+L37)*7)*100 -> 157.14286 | O37: 0 | P37: 0 | Q37: 8 | R37: 2 | S37: 6 | T37: =SUM(O37:S37) -> 16 | U37: =((((O37*1.5+(P37*3.5)+(Q37*5.5)+(R37*7.5)+(S37*12)))/3)/((F37+G37+H37+I37+J37+K37+L37)*7))*100 -> 207.93651 | V37: =C37+D37-T37 -> 0
B38: D | C38: 6 | D38: 8 | E38: =((($B$3*C38)+(12*D38))*$E$4)/7 -> 4.3928571 | F38: 3 | G38: 0 | H38: 0 | I38: 1 | J38: 0 | K38: 0 | M38: =(F38+G38+H38+L38)-E38 -> -1.3928571 | N38: =(((C38*4.5)+(12*D38))*$E$4)/((F38+G38+H38+I38+J38+K38+L38)*7)*100 -> 109.82143 | O38: 0 | P38: 4 | Q38: 8 | R38: 0 | S38: 6 | T38: =SUM(O38:S38) -> 18 | U38: =((((O38*1.5+(P38*3.5)+(Q38*5.5)+(R38*7.5)+(S38*12)))/3)/((F38+G38+H38+I38+J38+K38+L38)*7))*100 -> 154.7619 | V38: =C38+D38-T38 -> -4
B39: E | C39: 8 | D39: 6 | E39: =((($B$3*C39)+(12*D39))*$E$4)/7 -> 3.8571429 | F39: 3 | G39: 0 | H39: 0 | I39: 0 | J39: 0 | K39: 0 | M39: =(F39+G39+H39+L39)-E39 -> -0.85714286 | N39: =(((C39*4.5)+(12*D39))*$E$4)/((F39+G39+H39+I39+J39+K39+L39)*7)*100 -> 128.57143 | O39: 0 | P39: 0 | Q39: 8 | R39: 2 | S39: 3 | T39: =SUM(O39:S39) -> 13 | U39: =((((O39*1.5+(P39*3.5)+(Q39*5.5)+(R39*7.5)+(S39*12)))/3)/((F39+G39+H39+I39+J39+K39+L39)*7))*100 -> 150.79365 | V39: =C39+D39-T39 -> 1
A40: 11 | B40: N | C40: 8 | D40: 7 | E40: =((($B$3*C40)+(12*D40))*$E$4)/7 -> 4.2857143 | F40: 3 | G40: 0 | H40: 0 | I40: 0 | J40: 0 | K40: 0 | M40: =(F40+G40+H40+L40)-E40 -> -1.2857143 | N40: =(((C40*4.5)+(12*D40))*$E$4)/((F40+G40+H40+I40+J40+K40+L40)*7)*100 -> 142.85714 | O40: 0 | P40: 0 | Q40: 8 | R40: 3 | S40: 4 | T40: =SUM(O40:S40) -> 15 | U40: =((((O40*1.5+(P40*3.5)+(Q40*5.5)+(R40*7.5)+(S40*12)))/3)/((F40+G40+H40+I40+J40+K40+L40)*7))*100 -> 181.74603 | V40: =C40+D40-T40 -> 0
...

Sheet มค
A1: การคิด FTEรายวัน
A2: หอผู้ป่วย……...ประจำเดือน..............พ.ศ.................
A3: NN ผู้ป่วยต่อคน | B3: 4.5 | C3: สัดส่วนตามเวร | E3: N | I3: D | M3: E | O3: ค่าเวร | Q3: =((F103+F105)*240)+((G103+G105)*180) -> 1920 | S3: บาท
E4: 0.25 | I4: 0.4 | M4: 0.35 | O4: ค่าOT | Q4: =((I103+L103+I104+L104+I105+L105)*660)+((J103+J105+J104)*530) -> 660 | S4: บาท
A5: จำนวนพยาบาลมีจริงเดือนนี้ | E5: คน | F5: จำนวนวันราชการเดือนนี้ | N5: วัน
A6: จำนวนพยาบาลตามFTE | C6: =((C106*12)/(M5*7)+((D106*12)/(M5*7))) -> #DIV/0! | E6: คน | F6: ขาดเกิน | I6: =C5-C6 -> #DIV/0! | L6: คน | M6: product | N6: =((((C106*4.5)+(D106*12))/((F106+G106+H106+I106+J106+K106+L106)*7)))*100 -> 118.06723 | O6: product ตามประเภท | R6: =U106 -> 33.986928
